Workbook
Name CMI_FrameVGap: 0
Name CMI_FrameVPad: 1
Name CMI_FrameXOffset: 4
Name CMI_FrameYOffset: 7
Name MLG_FrameVPad: 1
Name MLG_FrameXOffset: 4
Name MLG_FrameYOffset: 5

Sheet Feuil2 (2)
A1: 45880 | B1: =WEEKNUM(A1) -> 33 | C1: =YEAR(A1) -> 2025 | D1: =52-B1+B2 -> 41
A2: 46171.5 | B2: =WEEKNUM(A2) -> 22 | C2: =YEAR(A2) -> 2026
B3: week | C3: scheduled | D3: Month | E3: MLG | F3: CMI
A5: 1 | B5: =IFERROR(IF($A5+$B$1-1>52,$B$1+A5-53&"/"&IF($A5+$B$1-1>52,$C$2,$C$1),$B$1+A5-1&"/"&IF($A5+$B$1-1>52,$C$2,$C$1)),NA()) -> 33/2025 | C5: 15 | D5: =IFERROR(IF(IFERROR( TEXT( DATE(YEAR(TODAY()),1,1) +7*(IF($A5+$B$1-1>52,$B$1+A5-53,$B$1+A5-1)-1), "mmmm" ),NA())&" "&IF($A5+$B$1-1>52,RIGHT($C$2,2),RIGHT($C$1,2))=D4,NA(),IFERROR( TEXT( DATE(YEAR(TODAY()),1,1) +7*(IF($A5+$B$1-1>52,$B$1+A5-53,$B$1+A5-1)-1), "mmmm" ),NA())&" "&IF($A5+$B$1-1>52,RIGHT($C$2,2),RIGHT($C$1,2))),NA()) -> août 25 | E5: #N/A | F5: #N/A
A6: =IFERROR(IF(A5+1>$D$1,NA(),A5+1),NA()) -> 2 | B6: =IFERROR(IF($A6+$B$1-1>52,$B$1+A6-53&"/"&IF($A6+$B$1-1>52,$C$2,$C$1),$B$1+A6-1&"/"&IF($A6+$B$1-1>52,$C$2,$C$1)),NA()) -> 34/2025 | C6: 25 | D6: =IFERROR(IFERROR( TEXT( DATE(YEAR(TODAY()),1,1) +7*(IF($A6+$B$1-1>52,$B$1+A6-53,$B$1+A6-1)-1), "mmmm" ),NA())&" "&IF($A6+$B$1-1>52,RIGHT($C$2,2),RIGHT($C$1,2)),NA()) -> août 25 | E6: #N/A | F6: #N/A
A7: =IFERROR(IF(A6+1>$D$1,NA(),A6+1),NA()) -> 3 | B7: =IFERROR(IF($A7+$B$1-1>52,$B$1+A7-53&"/"&IF($A7+$B$1-1>52,$C$2,$C$1),$B$1+A7-1&"/"&IF($A7+$B$1-1>52,$C$2,$C$1)),NA()) -> 35/2025 | C7: 34 | D7: =IFERROR(IFERROR( TEXT( DATE(YEAR(TODAY()),1,1) +7*(IF($A7+$B$1-1>52,$B$1+A7-53,$B$1+A7-1)-1), "mmmm" ),NA())&" "&IF($A7+$B$1-1>52,RIGHT($C$2,2),RIGHT($C$1,2)),NA()) -> août 25 | E7: #N/A | F7: #N/A
A8: =IFERROR(IF(A7+1>$D$1,NA(),A7+1),NA()) -> 4 | B8: =IFERROR(IF($A8+$B$1-1>52,$B$1+A8-53&"/"&IF($A8+$B$1-1>52,$C$2,$C$1),$B$1+A8-1&"/"&IF($A8+$B$1-1>52,$C$2,$C$1)),NA()) -> 36/2025 | C8: 43 | D8: =IFERROR(IFERROR( TEXT( DATE(YEAR(TODAY()),1,1) +7*(IF($A8+$B$1-1>52,$B$1+A8-53,$B$1+A8-1)-1), "mmmm" ),NA())&" "&IF($A8+$B$1-1>52,RIGHT($C$2,2),RIGHT($C$1,2)),NA()) -> septembre 25 | E8: #N/A | F8: #N/A
A9: =IFERROR(IF(A8+1>$D$1,NA(),A8+1),NA()) -> 5 | B9: =IFERROR(IF($A9+$B$1-1>52,$B$1+A9-53&"/"&IF($A9+$B$1-1>52,$C$2,$C$1),$B$1+A9-1&"/"&IF($A9+$B$1-1>52,$C$2,$C$1)),NA()) -> 37/2025 | C9: 56 | D9: =IFERROR(IFERROR( TEXT( DATE(YEAR(TODAY()),1,1) +7*(IF($A9+$B$1-1>52,$B$1+A9-53,$B$1+A9-1)-1), "mmmm" ),NA())&" "&IF($A9+$B$1-1>52,RIGHT($C$2,2),RIGHT($C$1,2)),NA()) -> septembre 25 | E9: #N/A | F9: #N/A
A10: =IFERROR(IF(A9+1>$D$1,NA(),A9+1),NA()) -> 6 | B10: =IFERROR(IF($A10+$B$1-1>52,$B$1+A10-53&"/"&IF($A10+$B$1-1>52,$C$2,$C$1),$B$1+A10-1&"/"&IF($A10+$B$1-1>52,$C$2,$C$1)),NA()) -> 38/2025 | C10: 56 | D10: =IFERROR(IFERROR( TEXT( DATE(YEAR(TODAY()),1,1) +7*(IF($A10+$B$1-1>52,$B$1+A10-53,$B$1+A10-1)-1), "mmmm" ),NA())&" "&IF($A10+$B$1-1>52,RIGHT($C$2,2),RIGHT($C$1,2)),NA()) -> septembre 25 | E10: #N/A | F10: #N/A
A11: =IFERROR(IF(A10+1>$D$1,NA(),A10+1),NA()) -> 7 | B11: =IFERROR(IF($A11+$B$1-1>52,$B$1+A11-53&"/"&IF($A11+$B$1-1>52,$C$2,$C$1),$B$1+A11-1&"/"&IF($A11+$B$1-1>52,$C$2,$C$1)),NA()) -> 39/2025 | C11: 68 | D11: =IFERROR(IFERROR( TEXT( DATE(YEAR(TODAY()),1,1) +7*(IF($A11+$B$1-1>52,$B$1+A11-53,$B$1+A11-1)-1), "mmmm" ),NA())&" "&IF($A11+$B$1-1>52,RIGHT($C$2,2),RIGHT($C$1,2)),NA()) -> septembre 25 | E11: #N/A | F11: #N/A
A12: =IFERROR(IF(A11+1>$D$1,NA(),A11+1),NA()) -> 8 | B12: =IFERROR(IF($A12+$B$1-1>52,$B$1+A12-53&"/"&IF($A12+$B$1-1>52,$C$2,$C$1),$B$1+A12-1&"/"&IF($A12+$B$1-1>52,$C$2,$C$1)),NA()) -> 40/2025 | C12: 77 | D12: =IFERROR(IFERROR( TEXT( DATE(YEAR(TODAY()),1,1) +7*(IF($A12+$B$1-1>52,$B$1+A12-53,$B$1+A12-1)-1), "mmmm" ),NA())&" "&IF($A12+$B$1-1>52,RIGHT($C$2,2),RIGHT($C$1,2)),NA()) -> octobre 25 | E12: #N/A | F12: #N/A
A13: =IFERROR(IF(A12+1>$D$1,NA(),A12+1),NA()) -> 9 | B13: =IFERROR(IF($A13+$B$1-1>52,$B$1+A13-53&"/"&IF($A13+$B$1-1>52,$C$2,$C$1),$B$1+A13-1&"/"&IF($A13+$B$1-1>52,$C$2,$C$1)),NA()) -> 41/2025 | C13: 89 | D13: =IFERROR(IFERROR( TEXT( DATE(YEAR(TODAY()),1,1) +7*(IF($A13+$B$1-1>52,$B$1+A13-53,$B$1+A13-1)-1), "mmmm" ),NA())&" "&IF($A13+$B$1-1>52,RIGHT($C$2,2),RIGHT($C$1,2)),NA()) -> octobre 25 | E13: #N/A | F13: #N/A
A14: =IFERROR(IF(A13+1>$D$1,NA(),A13+1),NA()) -> 10 | B14: =IFERROR(IF($A14+$B$1-1>52,$B$1+A14-53&"/"&IF($A14+$B$1-1>52,$C$2,$C$1),$B$1+A14-1&"/"&IF($A14+$B$1-1>52,$C$2,$C$1)),NA()) -> 42/2025 | C14: 115 | D14: =IFERROR(IFERROR( TEXT( DATE(YEAR(TODAY()),1,1) +7*(IF($A14+$B$1-1>52,$B$1+A14-53,$B$1+A14-1)-1), "mmmm" ),NA())&" "&IF($A14+$B$1-1>52,RIGHT($C$2,2),RIGHT($C$1,2)),NA()) -> octobre 25 | E14: #N/A | F14: #N/A
A15: =IFERROR(IF(A14+1>$D$1,NA(),A14+1),NA()) -> 11 | B15: =IFERROR(IF($A15+$B$1-1>52,$B$1+A15-53&"/"&IF($A15+$B$1-1>52,$C$2,$C$1),$B$1+A15-1&"/"&IF($A15+$B$1-1>52,$C$2,$C$1)),NA()) -> 43/2025 | C15: 143 | D15: =IFERROR(IFERROR( TEXT( DATE(YEAR(TODAY()),1,1) +7*(IF($A15+$B$1-1>52,$B$1+A15-53,$B$1+A15-1)-1), "mmmm" ),NA())&" "&IF($A15+$B$1-1>52,RIGHT($C$2,2),RIGHT($C$1,2)),NA()) -> octobre 25 | E15: #N/A | F15: #N/A
A16: =IFERROR(IF(A15+1>$D$1,NA(),A15+1),NA()) -> 12 | B16: =IFERROR(IF($A16+$B$1-1>52,$B$1+A16-53&"/"&IF($A16+$B$1-1>52,$C$2,$C$1),$B$1+A16-1&"/"&IF($A16+$B$1-1>52,$C$2,$C$1)),NA()) -> 44/2025 | C16: 170 | D16: =IFERROR(IFERROR( TEXT( DATE(YEAR(TODAY()),1,1) +7*(IF($A16+$B$1-1>52,$B$1+A16-53,$B$1+A16-1)-1), "mmmm" ),NA())&" "&IF($A16+$B$1-1>52,RIGHT($C$2,2),RIGHT($C$1,2)),NA()) -> octobre 25 | E16: #N/A | F16: #N/A
A17: =IFERROR(IF(A16+1>$D$1,NA(),A16+1),NA()) -> 13 | B17: =IFERROR(IF($A17+$B$1-1>52,$B$1+A17-53&"/"&IF($A17+$B$1-1>52,$C$2,$C$1),$B$1+A17-1&"/"&IF($A17+$B$1-1>52,$C$2,$C$1)),NA()) -> 45/2025 | C17: 193 | D17: =IFERROR(IFERROR( TEXT( DATE(YEAR(TODAY()),1,1) +7*(IF($A17+$B$1-1>52,$B$1+A17-53,$B$1+A17-1)-1), "mmmm" ),NA())&" "&IF($A17+$B$1-1>52,RIGHT($C$2,2),RIGHT($C$1,2)),NA()) -> novembre 25 | E17: #N/A | F17: #N/A
... A26: =IFERROR(IF(A25+1>$D$1,NA(),A25+1),NA()) -> 22 | B26: =IFERROR(IF($A26+$B$1-1>52,$B$1+A26-53&"/"&IF($A26+$B$1-1>52,$C$2,$C$1),$B$1+A26-1&"/"&IF($A26+$B$1-1>52,$C$2,$C$1)),NA()) -> 2/2026 | C26: 243 | D26: =IFERROR(IFERROR( TEXT( DATE(YEAR(TODAY()),1,1) +7*(IF($A26+$B$1-1>52,$B$1+A26-53,$B$1+A26-1)-1), "mmmm" ),NA())&" "&IF($A26+$B$1-1>52,RIGHT($C$2,2),RIGHT($C$1,2)),NA()) -> janvier 26 | E26: #N/A | F26: #N/A
A27: =IFERROR(IF(A26+1>$D$1,NA(),A26+1),NA()) -> 23 | B27: =IFERROR(IF($A27+$B$1-1>52,$B$1+A27-53&"/"&IF($A27+$B$1-1>52,$C$2,$C$1),$B$1+A27-1&"/"&IF($A27+$B$1-1>52,$C$2,$C$1)),NA()) -> 3/2026 | C27: 251 | D27: =IFERROR(IFERROR( TEXT( DATE(YEAR(TODAY()),1,1) +7*(IF($A27+$B$1-1>52,$B$1+A27-53,$B$1+A27-1)-1), "mmmm" ),NA())&" "&IF($A27+$B$1-1>52,RIGHT($C$2,2),RIGHT($C$1,2)),NA()) -> janvier 26 | E27: #N/A | F27: #N/A | G27: =IF($A5+$B$1-1>52,$B$1+$A5-53,$B$1+$A5-1) -> 33 | H27: =IF($A5+$B$1-1>52,$C$2,$C$1) -> 2025
A28: =IFERROR(IF(A27+1>$D$1,NA(),A27+1),NA()) -> 24 | B28: =IFERROR(IF($A28+$B$1-1>52,$B$1+A28-53&"/"&IF($A28+$B$1-1>52,$C$2,$C$1),$B$1+A28-1&"/"&IF($A28+$B$1-1>52,$C$2,$C$1)),NA()) -> 4/2026 | C28: 269 | D28: =IFERROR(IFERROR( TEXT( DATE(YEAR(TODAY()),1,1) +7*(IF($A28+$B$1-1>52,$B$1+A28-53,$B$1+A28-1)-1), "mmmm" ),NA())&" "&IF($A28+$B$1-1>52,RIGHT($C$2,2),RIGHT($C$1,2)),NA()) -> janvier 26 | E28: #N/A | F28: #N/A | G28: =_xlfn.ISOWEEKNUM(TODAY()) -> 34
A29: =IFERROR(IF(A28+1>$D$1,NA(),A28+1),NA()) -> 25 | B29: =IFERROR(IF($A29+$B$1-1>52,$B$1+A29-53&"/"&IF($A29+$B$1-1>52,$C$2,$C$1),$B$1+A29-1&"/"&IF($A29+$B$1-1>52,$C$2,$C$1)),NA()) -> 5/2026 | C29: 290 | D29: =IFERROR(IFERROR( TEXT( DATE(YEAR(TODAY()),1,1) +7*(IF($A29+$B$1-1>52,$B$1+A29-53,$B$1+A29-1)-1), "mmmm" ),NA())&" "&IF($A29+$B$1-1>52,RIGHT($C$2,2),RIGHT($C$1,2)),NA()) -> janvier 26 | E29: #N/A | F29: #N/A | G29: =YEAR(TODAY()) -> 2026
A30: =IFERROR(IF(A29+1>$D$1,NA(),A29+1),NA()) -> 26 | B30: =IFERROR(IF($A30+$B$1-1>52,$B$1+A30-53&"/"&IF($A30+$B$1-1>52,$C$2,$C$1),$B$1+A30-1&"/"&IF($A30+$B$1-1>52,$C$2,$C$1)),NA()) -> 6/2026 | C30: 314 | D30: =IFERROR(IFERROR( TEXT( DATE(YEAR(TODAY()),1,1) +7*(IF($A30+$B$1-1>52,$B$1+A30-53,$B$1+A30-1)-1), "mmmm" ),NA())&" "&IF($A30+$B$1-1>52,RIGHT($C$2,2),RIGHT($C$1,2)),NA()) -> février 26 | E30: #N/A | F30: #N/A
A31: =IFERROR(IF(A30+1>$D$1,NA(),A30+1),NA()) -> 27 | B31: =IFERROR(IF($A31+$B$1-1>52,$B$1+A31-53&"/"&IF($A31+$B$1-1>52,$C$2,$C$1),$B$1+A31-1&"/"&IF($A31+$B$1-1>52,$C$2,$C$1)),NA()) -> 7/2026 | C31: 333 | D31: =IFERROR(IFERROR( TEXT( DATE(YEAR(TODAY()),1,1) +7*(IF($A31+$B$1-1>52,$B$1+A31-53,$B$1+A31-1)-1), "mmmm" ),NA())&" "&IF($A31+$B$1-1>52,RIGHT($C$2,2),RIGHT($C$1,2)),NA()) -> février 26 | E31: #N/A | F31: #N/A
A32: =IFERROR(IF(A31+1>$D$1,NA(),A31+1),NA()) -> 28 | B32: =IFERROR(IF($A32+$B$1-1>52,$B$1+A32-53&"/"&IF($A32+$B$1-1>52,$C$2,$C$1),$B$1+A32-1&"/"&IF($A32+$B$1-1>52,$C$2,$C$1)),NA()) -> 8/2026 | C32: 357 | D32: =IFERROR(IFERROR( TEXT( DATE(YEAR(TODAY()),1,1) +7*(IF($A32+$B$1-1>52,$B$1+A32-53,$B$1+A32-1)-1), "mmmm" ),NA())&" "&IF($A32+$B$1-1>52,RIGHT($C$2,2),RIGHT($C$1,2)),NA()) -> février 26 | E32: #N/A | F32: #N/A
A33: =IFERROR(IF(A32+1>$D$1,NA(),A32+1),NA()) -> 29 | B33: =IFERROR(IF($A33+$B$1-1>52,$B$1+A33-53&"/"&IF($A33+$B$1-1>52,$C$2,$C$1),$B$1+A33-1&"/"&IF($A33+$B$1-1>52,$C$2,$C$1)),NA()) -> 9/2026 | C33: 373 | D33: =IFERROR(IFERROR( TEXT( DATE(YEAR(TODAY()),1,1) +7*(IF($A33+$B$1-1>52,$B$1+A33-53,$B$1+A33-1)-1), "mmmm" ),NA())&" "&IF($A33+$B$1-1>52,RIGHT($C$2,2),RIGHT($C$1,2)),NA()) -> février 26 | E33: #N/A | F33: #N/A
A34: =IFERROR(IF(A33+1>$D$1,NA(),A33+1),NA()) -> 30 | B34: =IFERROR(IF($A34+$B$1-1>52,$B$1+A34-53&"/"&IF($A34+$B$1-1>52,$C$2,$C$1),$B$1+A34-1&"/"&IF($A34+$B$1-1>52,$C$2,$C$1)),NA()) -> 10/2026 | C34: 390 | D34: =IFERROR(IFERROR( TEXT( DATE(YEAR(TODAY()),1,1) +7*(IF($A34+$B$1-1>52,$B$1+A34-53,$B$1+A34-1)-1), "mmmm" ),NA())&" "&IF($A34+$B$1-1>52,RIGHT($C$2,2),RIGHT($C$1,2)),NA()) -> mars 26 | E34: #N/A | F34: #N/A
A35: =IFERROR(IF(A34+1>$D$1,NA(),A34+1),NA()) -> 31 | B35: =IFERROR(IF($A35+$B$1-1>52,$B$1+A35-53&"/"&IF($A35+$B$1-1>52,$C$2,$C$1),$B$1+A35-1&"/"&IF($A35+$B$1-1>52,$C$2,$C$1)),NA()) -> 11/2026 | C35: 406 | D35: =IFERROR(IFERROR( TEXT( DATE(YEAR(TODAY()),1,1) +7*(IF($A35+$B$1-1>52,$B$1+A35-53,$B$1+A35-1)-1), "mmmm" ),NA())&" "&IF($A35+$B$1-1>52,RIGHT($C$2,2),RIGHT($C$1,2)),NA()) -> mars 26 | E35: #N/A | F35: #N/A
A36: =IFERROR(IF(A35+1>$D$1,NA(),A35+1),NA()) -> 32 | B36: =IFERROR(IF($A36+$B$1-1>52,$B$1+A36-53&"/"&IF($A36+$B$1-1>52,$C$2,$C$1),$B$1+A36-1&"/"&IF($A36+$B$1-1>52,$C$2,$C$1)),NA()) -> 12/2026 | C36: 409 | D36: =IFERROR(IFERROR( TEXT( DATE(YEAR(TODAY()),1,1) +7*(IF($A36+$B$1-1>52,$B$1+A36-53,$B$1+A36-1)-1), "mmmm" ),NA())&" "&IF($A36+$B$1-1>52,RIGHT($C$2,2),RIGHT($C$1,2)),NA()) -> mars 26 | E36: #N/A | F36: #N/A
A37: =IFERROR(IF(A36+1>$D$1,NA(),A36+1),NA()) -> 33 | B37: =IFERROR(IF($A37+$B$1-1>52,$B$1+A37-53&"/"&IF($A37+$B$1-1>52,$C$2,$C$1),$B$1+A37-1&"/"&IF($A37+$B$1-1>52,$C$2,$C$1)),NA()) -> 13/2026 | C37: 416 | D37: =IFERROR(IFERROR( TEXT( DATE(YEAR(TODAY()),1,1) +7*(IF($A37+$B$1-1>52,$B$1+A37-53,$B$1+A37-1)-1), "mmmm" ),NA())&" "&IF($A37+$B$1-1>52,RIGHT($C$2,2),RIGHT($C$1,2)),NA()) -> mars 26 | E37: #N/A | F37: #N/A
A38: =IFERROR(IF(A37+1>$D$1,NA(),A37+1),NA()) -> 34 | B38: =IFERROR(IF($A38+$B$1-1>52,$B$1+A38-53&"/"&IF($A38+$B$1-1>52,$C$2,$C$1),$B$1+A38-1&"/"&IF($A38+$B$1-1>52,$C$2,$C$1)),NA()) -> 14/2026 | C38: 438 | D38: =IFERROR(IFERROR( TEXT( DATE(YEAR(TODAY()),1,1) +7*(IF($A38+$B$1-1>52,$B$1+A38-53,$B$1+A38-1)-1), "mmmm" ),NA())&" "&IF($A38+$B$1-1>52,RIGHT($C$2,2),RIGHT($C$1,2)),NA()) -> avril 26 | E38: #N/A | F38: #N/A
A39: =IFERROR(IF(A38+1>$D$1,NA(),A38+1),NA()) -> 35 | B39: =IFERROR(IF($A39+$B$1-1>52,$B$1+A39-53&"/"&IF($A39+$B$1-1>52,$C$2,$C$1),$B$1+A39-1&"/"&IF($A39+$B$1-1>52,$C$2,$C$1)),NA()) -> 15/2026 | C39: 454 | D39: =IFERROR(IFERROR( TEXT( DATE(YEAR(TODAY()),1,1) +7*(IF($A39+$B$1-1>52,$B$1+A39-53,$B$1+A39-1)-1), "mmmm" ),NA())&" "&IF($A39+$B$1-1>52,RIGHT($C$2,2),RIGHT($C$1,2)),NA()) -> avril 26 | E39: #N/A | F39: #N/A
A40: =IFERROR(IF(A39+1>$D$1,NA(),A39+1),NA()) -> 36 | B40: =IFERROR(IF($A40+$B$1-1>52,$B$1+A40-53&"/"&IF($A40+$B$1-1>52,$C$2,$C$1),$B$1+A40-1&"/"&IF($A40+$B$1-1>52,$C$2,$C$1)),NA()) -> 16/2026 | C40: 479 | D40: =IFERROR(IFERROR( TEXT( DATE(YEAR(TODAY()),1,1) +7*(IF($A40+$B$1-1>52,$B$1+A40-53,$B$1+A40-1)-1), "mmmm" ),NA())&" "&IF($A40+$B$1-1>52,RIGHT($C$2,2),RIGHT($C$1,2)),NA()) -> avril 26 | E40: #N/A | F40: #N/A
A41: =IFERROR(IF(A40+1>$D$1,NA(),A40+1),NA()) -> 37 | B41: =IFERROR(IF($A41+$B$1-1>52,$B$1+A41-53&"/"&IF($A41+$B$1-1>52,$C$2,$C$1),$B$1+A41-1&"/"&IF($A41+$B$1-1>52,$C$2,$C$1)),NA()) -> 17/2026 | C41: 490 | D41: =IFERROR(IFERROR( TEXT( DATE(YEAR(TODAY()),1,1) +7*(IF($A41+$B$1-1>52,$B$1+A41-53,$B$1+A41-1)-1), "mmmm" ),NA())&" "&IF($A41+$B$1-1>52,RIGHT($C$2,2),RIGHT($C$1,2)),NA()) -> avril 26 | E41: #N/A | F41: #N/A
... A45: =IFERROR(IF(A44+1>$D$1,NA(),A44+1),NA()) -> 41 | B45: =IFERROR(IF($A45+$B$1-1>52,$B$1+A45-53&"/"&IF($A45+$B$1-1>52,$C$2,$C$1),$B$1+A45-1&"/"&IF($A45+$B$1-1>52,$C$2,$C$1)),NA()) -> 21/2026 | C45: 538 | D45: =IFERROR(IFERROR( TEXT( DATE(YEAR(TODAY()),1,1) +7*(IF($A45+$B$1-1>52,$B$1+A45-53,$B$1+A45-1)-1), "mmmm" ),NA())&" "&IF($A45+$B$1-1>52,RIGHT($C$2,2),RIGHT($C$1,2)),NA()) -> mai 26 | E45: #N/A | F45: #N/A
A46: =IFERROR(IF(A45+1>$D$1,NA(),A45+1),NA()) -> #N/A | B46: =IFERROR(IF($A46+$B$1-1>52,$B$1+A46-53&"/"&IF($A46+$B$1-1>52,$C$2,$C$1),$B$1+A46-1&"/"&IF($A46+$B$1-1>52,$C$2,$C$1)),NA()) -> #N/A | C46: #N/A | D46: =IFERROR(IFERROR( TEXT( DATE(YEAR(TODAY()),1,1) +7*(IF($A46+$B$1-1>52,$B$1+A46-53,$B$1+A46-1)-1), "mmmm" ),NA())&" "&IF($A46+$B$1-1>52,RIGHT($C$2,2),RIGHT($C$1,2)),NA()) -> #N/A | E46: #N/A | F46: #N/A
A47: =IFERROR(IF(A46+1>$D$1,NA(),A46+1),NA()) -> #N/A | B47: =IFERROR(IF($A47+$B$1-1>52,$B$1+A47-53&"/"&IF($A47+$B$1-1>52,$C$2,$C$1),$B$1+A47-1&"/"&IF($A47+$B$1-1>52,$C$2,$C$1)),NA()) -> #N/A | C47: #N/A | D47: =IFERROR(IFERROR( TEXT( DATE(YEAR(TODAY()),1,1) +7*(IF($A47+$B$1-1>52,$B$1+A47-53,$B$1+A47-1)-1), "mmmm" ),NA())&" "&IF($A47+$B$1-1>52,RIGHT($C$2,2),RIGHT($C$1,2)),NA()) -> #N/A | E47: #N/A | F47: #N/A
A48: =IFERROR(IF(A47+1>$D$1,NA(),A47+1),NA()) -> #N/A | B48: =IFERROR(IF($A48+$B$1-1>52,$B$1+A48-53&"/"&IF($A48+$B$1-1>52,$C$2,$C$1),$B$1+A48-1&"/"&IF($A48+$B$1-1>52,$C$2,$C$1)),NA()) -> #N/A | C48: #N/A | D48: =IFERROR(IFERROR( TEXT( DATE(YEAR(TODAY()),1,1) +7*(IF($A48+$B$1-1>52,$B$1+A48-53,$B$1+A48-1)-1), "mmmm" ),NA())&" "&IF($A48+$B$1-1>52,RIGHT($C$2,2),RIGHT($C$1,2)),NA()) -> #N/A | E48: #N/A | F48: #N/A
A49: =IFERROR(IF(A48+1>$D$1,NA(),A48+1),NA()) -> #N/A | B49: =IFERROR(IF($A49+$B$1-1>52,$B$1+A49-53&"/"&IF($A49+$B$1-1>52,$C$2,$C$1),$B$1+A49-1&"/"&IF($A49+$B$1-1>52,$C$2,$C$1)),NA()) -> #N/A | C49: #N/A | D49: =IFERROR(IFERROR( TEXT( DATE(YEAR(TODAY()),1,1) +7*(IF($A49+$B$1-1>52,$B$1+A49-53,$B$1+A49-1)-1), "mmmm" ),NA())&" "&IF($A49+$B$1-1>52,RIGHT($C$2,2),RIGHT($C$1,2)),NA()) -> #N/A | E49: #N/A | F49: #N/A
A50: =IFERROR(IF(A49+1>$D$1,NA(),A49+1),NA()) -> #N/A | B50: =IFERROR(IF($A50+$B$1-1>52,$B$1+A50-53&"/"&IF($A50+$B$1-1>52,$C$2,$C$1),$B$1+A50-1&"/"&IF($A50+$B$1-1>52,$C$2,$C$1)),NA()) -> #N/A | C50: #N/A | D50: =IFERROR(IFERROR( TEXT( DATE(YEAR(TODAY()),1,1) +7*(IF($A50+$B$1-1>52,$B$1+A50-53,$B$1+A50-1)-1), "mmmm" ),NA())&" "&IF($A50+$B$1-1>52,RIGHT($C$2,2),RIGHT($C$1,2)),NA()) -> #N/A | E50: #N/A | F50: #N/A
A51: =IFERROR(IF(A50+1>$D$1,NA(),A50+1),NA()) -> #N/A | B51: =IFERROR(IF($A51+$B$1-1>52,$B$1+A51-53&"/"&IF($A51+$B$1-1>52,$C$2,$C$1),$B$1+A51-1&"/"&IF($A51+$B$1-1>52,$C$2,$C$1)),NA()) -> #N/A | C51: #N/A | D51: =IFERROR(IFERROR( TEXT( DATE(YEAR(TODAY()),1,1) +7*(IF($A51+$B$1-1>52,$B$1+A51-53,$B$1+A51-1)-1), "mmmm" ),NA())&" "&IF($A51+$B$1-1>52,RIGHT($C$2,2),RIGHT($C$1,2)),NA()) -> #N/A | E51: #N/A | F51: #N/A
A52: =IFERROR(IF(A51+1>$D$1,NA(),A51+1),NA()) -> #N/A | B52: =IFERROR(IF($A52+$B$1-1>52,$B$1+A52-53&"/"&IF($A52+$B$1-1>52,$C$2,$C$1),$B$1+A52-1&"/"&IF($A52+$B$1-1>52,$C$2,$C$1)),NA()) -> #N/A | C52: #N/A | D52: =IFERROR(IFERROR( TEXT( DATE(YEAR(TODAY()),1,1) +7*(IF($A52+$B$1-1>52,$B$1+A52-53,$B$1+A52-1)-1), "mmmm" ),NA())&" "&IF($A52+$B$1-1>52,RIGHT($C$2,2),RIGHT($C$1,2)),NA()) -> #N/A | E52: #N/A | F52: #N/A
...

Sheet Dashboard
A1: ="WEEK N°"&WEEKNUM(TODAY())&"/"&YEAR(TODAY()) -> WEEK N°34/2026 | X1: CMI | AA1: MLG
A2: IAT Progression
V3: DELIVERY RATE | X3: 280.58364 | AA3: 311.18658
V5: P0 ITEMS NOT DELIVERED
V6: =IF(W6<>"",1,IF(AA6<>"",1,""))&IF(IF(W6<>"",1,IF(AA6<>"",1,""))<>"",".","") -> 1. | W6: CAPEX-017 | X6: Software | AA6: CAPEX-017 | AB6: Software
V7: =IF(W7<>"",LEFT(V6,LEN(V6)-1)+1,IF(AA7<>"",LEFT(V6,LEN(V6)-1)+1,""))&IF(IF(W7<>"",LEFT(V6,LEN(V6)-1)+1,IF(AA7<>"",LEFT(V6,LEN(V6)-1)+1,""))<>"",".","") -> 2. | W7: CAPEX-036 | X7: Elastic membrane manoscope | AA7: CAPEX-036 | AB7: Elastic membrane manoscope
V8: =IF(W8<>"",LEFT(V7,LEN(V7)-1)+1,IF(AA8<>"",LEFT(V7,LEN(V7)-1)+1,""))&IF(IF(W8<>"",LEFT(V7,LEN(V7)-1)+1,IF(AA8<>"",LEFT(V7,LEN(V7)-1)+1,""))<>"",".","") -> 3. | W8: CAPEX-056 | X8: Transformer training kit | AA8: CAPEX-056 | AB8: Transformer training kit
V9: =IF(W9<>"",LEFT(V8,LEN(V8)-1)+1,IF(AA9<>"",LEFT(V8,LEN(V8)-1)+1,""))&IF(IF(W9<>"",LEFT(V8,LEN(V8)-1)+1,IF(AA9<>"",LEFT(V8,LEN(V8)-1)+1,""))<>"",".","") -> 4. | W9: CAPEX-074 | X9: Acoustic kit | AA9: CAPEX-074 | AB9: Acoustic kit
V10: =IF(W10<>"",LEFT(V9,LEN(V9)-1)+1,IF(AA10<>"",LEFT(V9,LEN(V9)-1)+1,""))&IF(IF(W10<>"",LEFT(V9,LEN(V9)-1)+1,IF(AA10<>"",LEFT(V9,LEN(V9)-1)+1,""))<>"",".","") -> 5. | W10: CAPEX-077 | X10: Kit Electricity and electromagnetism | AA10: CAPEX-077 | AB10: Kit Electricity and electromagnetism
V11: =IF(W11<>"",LEFT(V10,LEN(V10)-1)+1,IF(AA11<>"",LEFT(V10,LEN(V10)-1)+1,""))&IF(IF(W11<>"",LEFT(V10,LEN(V10)-1)+1,IF(AA11<>"",LEFT(V10,LEN(V10)-1)+1,""))<>"",".","") -> 6. | AA11: CAPEX-080 | AB11: Power Kit
V12: =IF(W12<>"",LEFT(V11,LEN(V11)-1)+1,IF(AA12<>"",LEFT(V11,LEN(V11)-1)+1,""))&IF(IF(W12<>"",LEFT(V11,LEN(V11)-1)+1,IF(AA12<>"",LEFT(V11,LEN(V11)-1)+1,""))<>"",".","") -> 7. | AA12: CAPEX-081 | AB12: Electromagnetic induction
V13: =IF(W13<>"",LEFT(V12,LEN(V12)-1)+1,IF(AA13<>"",LEFT(V12,LEN(V12)-1)+1,""))&IF(IF(W13<>"",LEFT(V12,LEN(V12)-1)+1,IF(AA13<>"",LEFT(V12,LEN(V12)-1)+1,""))<>"",".","")
V14: =IF(W14<>"",LEFT(V13,LEN(V13)-1)+1,IF(AA14<>"",LEFT(V13,LEN(V13)-1)+1,""))&IF(IF(W14<>"",LEFT(V13,LEN(V13)-1)+1,IF(AA14<>"",LEFT(V13,LEN(V13)-1)+1,""))<>"",".","")
V15: =IF(W15<>"",LEFT(V14,LEN(V14)-1)+1,IF(AA15<>"",LEFT(V14,LEN(V14)-1)+1,""))&IF(IF(W15<>"",LEFT(V14,LEN(V14)-1)+1,IF(AA15<>"",LEFT(V14,LEN(V14)-1)+1,""))<>"",".","")
V16: =IF(W16<>"",LEFT(V15,LEN(V15)-1)+1,IF(AA16<>"",LEFT(V15,LEN(V15)-1)+1,""))&IF(IF(W16<>"",LEFT(V15,LEN(V15)-1)+1,IF(AA16<>"",LEFT(V15,LEN(V15)-1)+1,""))<>"",".","")
V17: =IF(W17<>"",LEFT(V16,LEN(V16)-1)+1,IF(AA17<>"",LEFT(V16,LEN(V16)-1)+1,""))&IF(IF(W17<>"",LEFT(V16,LEN(V16)-1)+1,IF(AA17<>"",LEFT(V16,LEN(V16)-1)+1,""))<>"",".","")
V18: =IF(W18<>"",LEFT(V17,LEN(V17)-1)+1,IF(AA18<>"",LEFT(V17,LEN(V17)-1)+1,""))&IF(IF(W18<>"",LEFT(V17,LEN(V17)-1)+1,IF(AA18<>"",LEFT(V17,LEN(V17)-1)+1,""))<>"",".","")
V19: =IF(W19<>"",LEFT(V18,LEN(V18)-1)+1,IF(AA19<>"",LEFT(V18,LEN(V18)-1)+1,""))&IF(IF(W19<>"",LEFT(V18,LEN(V18)-1)+1,IF(AA19<>"",LEFT(V18,LEN(V18)-1)+1,""))<>"",".","")
V20: =IF(W20<>"",LEFT(V19,LEN(V19)-1)+1,IF(AA20<>"",LEFT(V19,LEN(V19)-1)+1,""))&IF(IF(W20<>"",LEFT(V19,LEN(V19)-1)+1,IF(AA20<>"",LEFT(V19,LEN(V19)-1)+1,""))<>"",".","")
V21: =IF(W21<>"",LEFT(V20,LEN(V20)-1)+1,IF(AA21<>"",LEFT(V20,LEN(V20)-1)+1,""))&IF(IF(W21<>"",LEFT(V20,LEN(V20)-1)+1,IF(AA21<>"",LEFT(V20,LEN(V20)-1)+1,""))<>"",".","")
V22: =IF(W22<>"",LEFT(V21,LEN(V21)-1)+1,IF(AA22<>"",LEFT(V21,LEN(V21)-1)+1,""))&IF(IF(W22<>"",LEFT(V21,LEN(V21)-1)+1,IF(AA22<>"",LEFT(V21,LEN(V21)-1)+1,""))<>"",".","")
V23: =IF(W23<>"",LEFT(V22,LEN(V22)-1)+1,IF(AA23<>"",LEFT(V22,LEN(V22)-1)+1,""))&IF(IF(W23<>"",LEFT(V22,LEN(V22)-1)+1,IF(AA23<>"",LEFT(V22,LEN(V22)-1)+1,""))<>"",".","")
V24: =IF(W24<>"",LEFT(V23,LEN(V23)-1)+1,IF(AA24<>"",LEFT(V23,LEN(V23)-1)+1,""))&IF(IF(W24<>"",LEFT(V23,LEN(V23)-1)+1,IF(AA24<>"",LEFT(V23,LEN(V23)-1)+1,""))<>"",".","")
... V27: =IF(W27<>"",LEFT(V26,LEN(V26)-1)+1,IF(AA27<>"",LEFT(V26,LEN(V26)-1)+1,""))&IF(IF(W27<>"",LEFT(V26,LEN(V26)-1)+1,IF(AA27<>"",LEFT(V26,LEN(V26)-1)+1,""))<>"",".","")
A28: IAT attendance rate | V28: =IF(W28<>"",LEFT(V27,LEN(V27)-1)+1,IF(AA28<>"",LEFT(V27,LEN(V27)-1)+1,""))&IF(IF(W28<>"",LEFT(V27,LEN(V27)-1)+1,IF(AA28<>"",LEFT(V27,LEN(V27)-1)+1,""))<>"",".","")
A29: MLG | B29: ='KPI MLG_Old'!M139 -> #DIV/0! | M29: CMI | N29: ='KPI CMI'!E138 -> 0.96223958

Sheet Feuil1
E1: THEORIE | K1: Pratique
A2: IAT | B2: GRADE | C2: LESSON | E2: A | F2: B | G2: C | H2: VALIDATION | I2: D | K2: A | L2: B | M2: C | N2: VALIDATION | O2: D
A3: TASYA | B3: 10 | C3: 1.1.1 | D3: 3 | H3: =IF(AND(ISBLANK(E3),ISBLANK(F3),ISBLANK(G3)),FALSE,TRUE) -> FALSE | J3: 0
A4: TASYA | B4: 10 | C4: 2.1.1 | D4: 2 | H4: =IF(AND(ISBLANK(E4),ISBLANK(F4),ISBLANK(G4)),FALSE,TRUE) -> FALSE | J4: 1 | N4: =IF(AND(ISBLANK(K4),ISBLANK(L4),ISBLANK(M4)),FALSE,TRUE) -> FALSE
A5: TASYA | B5: 10 | C5: 2.1.2 | D5: 1 | H5: =IF(AND(ISBLANK(E5),ISBLANK(F5),ISBLANK(G5)),FALSE,TRUE) -> FALSE | J5: 3 | N5: =IF(AND(ISBLANK(K5),ISBLANK(L5),ISBLANK(M5)),FALSE,TRUE) -> FALSE
A6: TASYA | B6: 10 | C6: 2.1.3 | D6: 1 | H6: =IF(AND(ISBLANK(E6),ISBLANK(F6),ISBLANK(G6)),FALSE,TRUE) -> FALSE | J6: 0
A7: TASYA | B7: 10 | C7: 2.1.4 | D7: 1 | H7: =IF(AND(ISBLANK(E7),ISBLANK(F7),ISBLANK(G7)),FALSE,TRUE) -> FALSE | J7: 1 | N7: =IF(AND(ISBLANK(K7),ISBLANK(L7),ISBLANK(M7)),FALSE,TRUE) -> FALSE
A8: TASYA | B8: 10 | C8: 2.1.5 | D8: 1 | H8: =IF(AND(ISBLANK(E8),ISBLANK(F8),ISBLANK(G8)),FALSE,TRUE) -> FALSE | J8: 1 | N8: =IF(AND(ISBLANK(K8),ISBLANK(L8),ISBLANK(M8)),FALSE,TRUE) -> FALSE
A9: TASYA | B9: 10 | C9: 2.1.6 | D9: 1 | H9: =IF(AND(ISBLANK(E9),ISBLANK(F9),ISBLANK(G9)),FALSE,TRUE) -> FALSE | J9: 1 | N9: =IF(AND(ISBLANK(K9),ISBLANK(L9),ISBLANK(M9)),FALSE,TRUE) -> FALSE
A10: TASYA | B10: 10 | C10: 2.2.1 | D10: 1 | H10: =IF(AND(ISBLANK(E10),ISBLANK(F10),ISBLANK(G10)),FALSE,TRUE) -> FALSE | J10: 0
A11: TASYA | B11: 10 | C11: 2.3.1 | D11: 1 | H11: =IF(AND(ISBLANK(E11),ISBLANK(F11),ISBLANK(G11)),FALSE,TRUE) -> FALSE | J11: 0
A12: TASYA | B12: 10 | C12: 2.3.2 | D12: 1 | H12: =IF(AND(ISBLANK(E12),ISBLANK(F12),ISBLANK(G12)),FALSE,TRUE) -> FALSE | J12: 2 | N12: =IF(AND(ISBLANK(K12),ISBLANK(L12),ISBLANK(M12)),FALSE,TRUE) -> FALSE
A13: TASYA | B13: 10 | C13: 2.3.3 | D13: 1 | H13: =IF(AND(ISBLANK(E13),ISBLANK(F13),ISBLANK(G13)),FALSE,TRUE) -> FALSE | J13: 1 | N13: =IF(AND(ISBLANK(K13),ISBLANK(L13),ISBLANK(M13)),FALSE,TRUE) -> FALSE
A14: TASYA | B14: 10 | C14: 2.3.4 | D14: 1 | H14: =IF(AND(ISBLANK(E14),ISBLANK(F14),ISBLANK(G14)),FALSE,TRUE) -> FALSE | J14: 1 | N14: =IF(AND(ISBLANK(K14),ISBLANK(L14),ISBLANK(M14)),FALSE,TRUE) -> FALSE
A15: TASYA | B15: 10 | C15: 2.4.1 | D15: 3 | H15: =IF(AND(ISBLANK(E15),ISBLANK(F15),ISBLANK(G15)),FALSE,TRUE) -> FALSE | J15: 0
A16: TASYA | B16: 10 | C16: 2.5.1 | D16: 2 | H16: =IF(AND(ISBLANK(E16),ISBLANK(F16),ISBLANK(G16)),FALSE,TRUE) -> FALSE | J16: 2 | N16: =IF(AND(ISBLANK(K16),ISBLANK(L16),ISBLANK(M16)),FALSE,TRUE) -> FALSE
A17: TASYA | B17: 10 | C17: 3A.1.1 | D17: 4 | H17: =IF(AND(ISBLANK(E17),ISBLANK(F17),ISBLANK(G17)),FALSE,TRUE) -> FALSE | J17: 0
A18: TASYA | B18: 10 | C18: 3A.2.1 | D18: 2 | H18: =IF(AND(ISBLANK(E18),ISBLANK(F18),ISBLANK(G18)),FALSE,TRUE) -> FALSE | J18: 0
A19: TASYA | B19: 10 | C19: 3A.3.1 | D19: 0 | H19: =IF(AND(ISBLANK(E19),ISBLANK(F19),ISBLANK(G19)),FALSE,TRUE) -> FALSE | J19: 8 | N19: =IF(AND(ISBLANK(K19),ISBLANK(L19),ISBLANK(M19)),FALSE,TRUE) -> FALSE
A20: TASYA | B20: 10 | C20: 3A.3.2 | D20: 0 | H20: =IF(AND(ISBLANK(E20),ISBLANK(F20),ISBLANK(G20)),FALSE,TRUE) -> FALSE | J20: 8 | N20: =IF(AND(ISBLANK(K20),ISBLANK(L20),ISBLANK(M20)),FALSE,TRUE) -> FALSE
A21: TASYA | B21: 10 | C21: 4A.1.1 | D21: 2 | H21: =IF(AND(ISBLANK(E21),ISBLANK(F21),ISBLANK(G21)),FALSE,TRUE) -> FALSE | J21: 0
A22: TASYA | B22: 10 | C22: 4A.1.2 | D22: 1 | H22: =IF(AND(ISBLANK(E22),ISBLANK(F22),ISBLANK(G22)),FALSE,TRUE) -> FALSE | J22: 2 | N22: =IF(AND(ISBLANK(K22),ISBLANK(L22),ISBLANK(M22)),FALSE,TRUE) -> FALSE
A23: TASYA | B23: 10 | C23: 4A.1.3 | D23: 1 | H23: =IF(AND(ISBLANK(E23),ISBLANK(F23),ISBLANK(G23)),FALSE,TRUE) -> FALSE | J23: 2 | N23: =IF(AND(ISBLANK(K23),ISBLANK(L23),ISBLANK(M23)),FALSE,TRUE) -> FALSE
A24: TASYA | B24: 10 | C24: 4A.1.4 | D24: 1 | H24: =IF(AND(ISBLANK(E24),ISBLANK(F24),ISBLANK(G24)),FALSE,TRUE) -> FALSE | J24: 0
A25: TASYA | B25: 10 | C25: 4A.1.5 | D25: 1 | H25: =IF(AND(ISBLANK(E25),ISBLANK(F25),ISBLANK(G25)),FALSE,TRUE) -> FALSE | J25: 0
A26: TASYA | B26: 10 | C26: 4A.1.6 | D26: 1 | H26: =IF(AND(ISBLANK(E26),ISBLANK(F26),ISBLANK(G26)),FALSE,TRUE) -> FALSE | J26: 2 | N26: =IF(AND(ISBLANK(K26),ISBLANK(L26),ISBLANK(M26)),FALSE,TRUE) -> FALSE
A27: TASYA | B27: 10 | C27: 4A.2.1 | D27: 1 | H27: =IF(AND(ISBLANK(E27),ISBLANK(F27),ISBLANK(G27)),FALSE,TRUE) -> FALSE | J27: 0
A28: TASYA | B28: 10 | C28: 4A.2.2 | D28: 1 | H28: =IF(AND(ISBLANK(E28),ISBLANK(F28),ISBLANK(G28)),FALSE,TRUE) -> FALSE | J28: 2 | N28: =IF(AND(ISBLANK(K28),ISBLANK(L28),ISBLANK(M28)),FALSE,TRUE) -> FALSE
A29: TASYA | B29: 10 | C29: 4A.2.3 | D29: 1 | H29: =IF(AND(ISBLANK(E29),ISBLANK(F29),ISBLANK(G29)),FALSE,TRUE) -> FALSE | J29: 2 | N29: =IF(AND(ISBLANK(K29),ISBLANK(L29),ISBLANK(M29)),FALSE,TRUE) -> FALSE
A30: TASYA | B30: 10 | C30: 4A.3.1 | D30: 1 | H30: =IF(AND(ISBLANK(E30),ISBLANK(F30),ISBLANK(G30)),FALSE,TRUE) -> FALSE | J30: 2 | N30: =IF(AND(ISBLANK(K30),ISBLANK(L30),ISBLANK(M30)),FALSE,TRUE) -> FALSE
A31: TASYA | B31: 10 | C31: 4A.3.2 | D31: 1 | H31: =IF(AND(ISBLANK(E31),ISBLANK(F31),ISBLANK(G31)),FALSE,TRUE) -> FALSE | J31: 0
A32: TASYA | B32: 10 | C32: 4A.3.3 | D32: 1 | H32: =IF(AND(ISBLANK(E32),ISBLANK(F32),ISBLANK(G32)),FALSE,TRUE) -> FALSE | J32: 3 | N32: =IF(AND(ISBLANK(K32),ISBLANK(L32),ISBLANK(M32)),FALSE,TRUE) -> FALSE
A33: TASYA | B33: 10 | C33: 5A.1.1 | D33: 4 | H33: =IF(AND(ISBLANK(E33),ISBLANK(F33),ISBLANK(G33)),FALSE,TRUE) -> FALSE | J33: 4 | N33: =IF(AND(ISBLANK(K33),ISBLANK(L33),ISBLANK(M33)),FALSE,TRUE) -> FALSE
A34: TASYA | B34: 10 | C34: 5A.1.2 | D34: 3 | H34: =IF(AND(ISBLANK(E34),ISBLANK(F34),ISBLANK(G34)),FALSE,TRUE) -> FALSE | J34: 0
A35: TASYA | B35: 10 | C35: 5A.2.1 | D35: 2 | H35: =IF(AND(ISBLANK(E35),ISBLANK(F35),ISBLANK(G35)),FALSE,TRUE) -> FALSE | J35: 4 | N35: =IF(AND(ISBLANK(K35),ISBLANK(L35),ISBLANK(M35)),FALSE,TRUE) -> FALSE
A36: TASYA | B36: 10 | C36: 5A.2.2 | D36: 4 | H36: =IF(AND(ISBLANK(E36),ISBLANK(F36),ISBLANK(G36)),FALSE,TRUE) -> FALSE | J36: 4 | N36: =IF(AND(ISBLANK(K36),ISBLANK(L36),ISBLANK(M36)),FALSE,TRUE) -> FALSE
A37: TASYA | B37: 10 | C37: 6A.1.1 | D37: 2 | H37: =IF(AND(ISBLANK(E37),ISBLANK(F37),ISBLANK(G37)),FALSE,TRUE) -> FALSE | J37: 2 | N37: =IF(AND(ISBLANK(K37),ISBLANK(L37),ISBLANK(M37)),FALSE,TRUE) -> FALSE
A38: TASYA | B38: 10 | C38: 6A.1.2 | D38: 2 | H38: =IF(AND(ISBLANK(E38),ISBLANK(F38),ISBLANK(G38)),FALSE,TRUE) -> FALSE | J38: 3 | N38: =IF(AND(ISBLANK(K38),ISBLANK(L38),ISBLANK(M38)),FALSE,TRUE) -> FALSE
A39: TASYA | B39: 10 | C39: 6A.2.1 | D39: 1 | H39: =IF(AND(ISBLANK(E39),ISBLANK(F39),ISBLANK(G39)),FALSE,TRUE) -> FALSE | J39: 0
A40: TASYA | B40: 10 | C40: 6A.2.2 | D40: 1 | H40: =IF(AND(ISBLANK(E40),ISBLANK(F40),ISBLANK(G40)),FALSE,TRUE) -> FALSE | J40: 4 | N40: =IF(AND(ISBLANK(K40),ISBLANK(L40),ISBLANK(M40)),FALSE,TRUE) -> FALSE
...

Sheet TH_CMI GRADE 10
C1: A | D1: ABSENT | P1: F | Q1: FAILED (STEPS C/D ONLY) | AR1: =IF(IF(_xlfn.XLOOKUP(LEFT(A46,LEN(A46)-2),'TH_CMI GRADE 10'!$B$7:$B$49,'TH_CMI GRADE 10'!$AS$7:$AS$49,"",0,1)=0,"",_xlfn.XLOOKUP(LEFT(A46,LEN(A46)-2),'TH_CMI GRADE 10'!$B$7:$B$49,'TH_CMI GRADE 10'!$AS$7:$AS$49,"",0,1))<=TODAY(),TRUE,FALSE) -> FALSE
C2: P | D2: PRESENT | P2: R | Q2: REMEDIAL
C3: O | D3: OPTIONAL | P3: Cours Planifié
C4: X | D4: PARTIAL PRESENCE | P4: A CORRIGER
C5: DIKI | I5: RIZKI | O5: GITA | U5: GHATA | AA5: RAHMAT | AG5: AYUTYASTUTI | AM5: KARTIKA | AS5: DATE DE DIFFUSION | AV5: DIKI | AY5: RIZKI | BB5: GITA | BE5: GHATA | BH5: RAHMAT | BK5: AYUTYASTUTI | BN5: KARTIKA
A6: Batch#1 | C6: A | D6: B | E6: C1 | F6: C2 | G6: C3 | H6: D | I6: A | J6: B | K6: C1 | L6: C2 | M6: C3 | N6: D | O6: A | P6: B | Q6: C1 | R6: C2 | S6: C3 | T6: D | U6: A | V6: B | W6: C1 | X6: C2 | Y6: C3 | Z6: D | AA6: A | AB6: B | AC6: C1 | AD6: C2 | AE6: C3 | AF6: D | AG6: A | AH6: B | AI6: C1 | AJ6: C2 | AK6: C3 | AL6: D | AM6: A | AN6: B | AO6: C1 | AP6: C2 | AQ6: C3 | AR6: D | AS6: A | AT6: B | AU6: D | AV6: C1 | AW6: C2 | AX6: C3 | AY6: C1 | AZ6: C2 | BA6: C3 | BB6: C1 | BC6: C2 | BD6: C3 | BE6: C1 | BF6: C2 | BG6: C3 | BH6: C1 | BI6: C2 | BJ6: C3 | BK6: C1 | BL6: C2 | BM6: C3 | BN6: C1 | BO6: C2 | BP6: C3 | BR6: Batch#2
A7: =IF(OR(D7<>"",V7<>"",J7<>"",P7<>"",AB7<>"",AH7<>"",AN7<>"",AT7<>""),TRUE,FALSE) -> TRUE | B7: 1.1.1 | C7: P | D7: P | E7: P | H7: A | U7: P | V7: P | W7: P | Z7: P | AS7: 45894 | AT7: 45954 | AU7: 46231 | AV7: 45986 | BE7: 45918 | BQ7: =_xlfn.TEXTBEFORE($B7,".",2) -> 1.1 | BR7: =IF(OR(H7<>"",N7<>"",T7<>"",Z7<>"",AF7<>"",AL7<>"",AR7<>"",AU7<>""),TRUE,FALSE) -> TRUE
A8: =IF(OR(D8<>"",V8<>"",J8<>"",P8<>"",AB8<>"",AH8<>"",AN8<>"",AT8<>""),TRUE,FALSE) -> TRUE | B8: 2.1.1 | AA8: P | AB8: P | AC8: P | AG8: P | AH8: P | AI8: P | AS8: 45902 | AT8: 46064 | BH8: 45952 | BK8: 45936 | BQ8: =_xlfn.TEXTBEFORE($B8,".",2) -> 2.1 | BR8: =IF(OR(H8<>"",N8<>"",T8<>"",Z8<>"",AF8<>"",AL8<>"",AR8<>"",AU8<>""),TRUE,FALSE) -> FALSE
A9: =IF(OR(D9<>"",V9<>"",J9<>"",P9<>"",AB9<>"",AH9<>"",AN9<>"",AT9<>""),TRUE,FALSE) -> TRUE | B9: 2.1.2 | AA9: P | AB9: P | AC9: P | AG9: P | AH9: P | AI9: P | AS9: 45904 | AT9: 46065 | BH9: 45964 | BK9: 45922 | BQ9: =_xlfn.TEXTBEFORE($B9,".",2) -> 2.1 | BR9: =IF(OR(H9<>"",N9<>"",T9<>"",Z9<>"",AF9<>"",AL9<>"",AR9<>"",AU9<>""),TRUE,FALSE) -> FALSE
A10: =IF(OR(D10<>"",V10<>"",J10<>"",P10<>"",AB10<>"",AH10<>"",AN10<>"",AT10<>""),TRUE,FALSE) -> TRUE | B10: 2.1.3 | AA10: P | AB10: P | AC10: P | AG10: P | AH10: P | AI10: P | AS10: 45904 | AT10: 46049 | BH10: 45964 | BK10: 45937 | BQ10: =_xlfn.TEXTBEFORE($B10,".",2) -> 2.1 | BR10: =IF(OR(H10<>"",N10<>"",T10<>"",Z10<>"",AF10<>"",AL10<>"",AR10<>"",AU10<>""),TRUE,FALSE) -> FALSE
A11: =IF(OR(D11<>"",V11<>"",J11<>"",P11<>"",AB11<>"",AH11<>"",AN11<>"",AT11<>""),TRUE,FALSE) -> TRUE | B11: 2.1.4 | AA11: P | AB11: P | AC11: P | AG11: P | AH11: P | AI11: P | AS11: 45904 | AT11: 46034 | BH11: 45965 | BK11: 45939 | BQ11: =_xlfn.TEXTBEFORE($B11,".",2) -> 2.1 | BR11: =IF(OR(H11<>"",N11<>"",T11<>"",Z11<>"",AF11<>"",AL11<>"",AR11<>"",AU11<>""),TRUE,FALSE) -> FALSE
A12: =IF(OR(D12<>"",V12<>"",J12<>"",P12<>"",AB12<>"",AH12<>"",AN12<>"",AT12<>""),TRUE,FALSE) -> TRUE | B12: 2.1.5 | AA12: P | AB12: P | AC12: P | AG12: P | AH12: P | AI12: P | AS12: 45908 | AT12: 46035 | BH12: 45965 | BK12: 45944 | BQ12: =_xlfn.TEXTBEFORE($B12,".",2) -> 2.1 | BR12: =IF(OR(H12<>"",N12<>"",T12<>"",Z12<>"",AF12<>"",AL12<>"",AR12<>"",AU12<>""),TRUE,FALSE) -> FALSE
A13: =IF(OR(D13<>"",V13<>"",J13<>"",P13<>"",AB13<>"",AH13<>"",AN13<>"",AT13<>""),TRUE,FALSE) -> TRUE | B13: 2.1.6 | AA13: P | AB13: P | AC13: P | AG13: P | AH13: P | AI13: P | AS13: 45908 | AT13: 46049 | BH13: 45966 | BK13: 45957 | BQ13: =_xlfn.TEXTBEFORE($B13,".",2) -> 2.1 | BR13: =IF(OR(H13<>"",N13<>"",T13<>"",Z13<>"",AF13<>"",AL13<>"",AR13<>"",AU13<>""),TRUE,FALSE) -> FALSE
A14: =IF(OR(D14<>"",V14<>"",J14<>"",P14<>"",AB14<>"",AH14<>"",AN14<>"",AT14<>""),TRUE,FALSE) -> TRUE | B14: 2.2.1 | AA14: P | AB14: P | AC14: P | AG14: P | AH14: P | AI14: P | AS14: 45909 | AT14: 46034 | BH14: 45966 | BK14: 45945 | BQ14: =_xlfn.TEXTBEFORE($B14,".",2) -> 2.2 | BR14: =IF(OR(H14<>"",N14<>"",T14<>"",Z14<>"",AF14<>"",AL14<>"",AR14<>"",AU14<>""),TRUE,FALSE) -> FALSE
A15: =IF(OR(D15<>"",V15<>"",J15<>"",P15<>"",AB15<>"",AH15<>"",AN15<>"",AT15<>""),TRUE,FALSE) -> TRUE | B15: 2.3.1 | AA15: P | AB15: P | AC15: P | AG15: P | AH15: P | AI15: P | AS15: 45909 | AT15: 46035 | BH15: 45967 | BK15: 45946 | BQ15: =_xlfn.TEXTBEFORE($B15,".",2) -> 2.3 | BR15: =IF(OR(H15<>"",N15<>"",T15<>"",Z15<>"",AF15<>"",AL15<>"",AR15<>"",AU15<>""),TRUE,FALSE) -> FALSE
A16: =IF(OR(D16<>"",V16<>"",J16<>"",P16<>"",AB16<>"",AH16<>"",AN16<>"",AT16<>""),TRUE,FALSE) -> TRUE | B16: 2.3.2 | AA16: P | AB16: P | AC16: P | AG16: P | AH16: P | AI16: P | AS16: 45910 | AT16: 46065 | BH16: 45967 | BK16: 45952 | BQ16: =_xlfn.TEXTBEFORE($B16,".",2) -> 2.3 | BR16: =IF(OR(H16<>"",N16<>"",T16<>"",Z16<>"",AF16<>"",AL16<>"",AR16<>"",AU16<>""),TRUE,FALSE) -> FALSE
A17: =IF(OR(D17<>"",V17<>"",J17<>"",P17<>"",AB17<>"",AH17<>"",AN17<>"",AT17<>""),TRUE,FALSE) -> TRUE | B17: 2.3.3 | AA17: P | AB17: P | AC17: P | AG17: P | AH17: P | AI17: P | AS17: 45910 | AT17: 46071 | BH17: 45971 | BK17: 45952 | BQ17: =_xlfn.TEXTBEFORE($B17,".",2) -> 2.3 | BR17: =IF(OR(H17<>"",N17<>"",T17<>"",Z17<>"",AF17<>"",AL17<>"",AR17<>"",AU17<>""),TRUE,FALSE) -> FALSE
A18: =IF(OR(D18<>"",V18<>"",J18<>"",P18<>"",AB18<>"",AH18<>"",AN18<>"",AT18<>""),TRUE,FALSE) -> TRUE | B18: 2.3.4 | AA18: P | AB18: P | AC18: P | AG18: P | AH18: P | AI18: P | AS18: 45911 | AT18: 46071 | BH18: 45973 | BK18: 45953 | BQ18: =_xlfn.TEXTBEFORE($B18,".",2) -> 2.3 | BR18: =IF(OR(H18<>"",N18<>"",T18<>"",Z18<>"",AF18<>"",AL18<>"",AR18<>"",AU18<>""),TRUE,FALSE) -> FALSE
A19: =IF(OR(D19<>"",V19<>"",J19<>"",P19<>"",AB19<>"",AH19<>"",AN19<>"",AT19<>""),TRUE,FALSE) -> TRUE | B19: 2.4.1 | AA19: P | AB19: P | AC19: P | AF19: P | AG19: P | AH19: P | AI19: P | AL19: P | AS19: 45915 | AT19: 45975 | AU19: 46253 | BH19: 45973 | BK19: 45959 | BQ19: =_xlfn.TEXTBEFORE($B19,".",2) -> 2.4 | BR19: =IF(OR(H19<>"",N19<>"",T19<>"",Z19<>"",AF19<>"",AL19<>"",AR19<>"",AU19<>""),TRUE,FALSE) -> TRUE
A20: =IF(OR(D20<>"",V20<>"",J20<>"",P20<>"",AB20<>"",AH20<>"",AN20<>"",AT20<>""),TRUE,FALSE) -> TRUE | B20: 2.5.1 | AA20: P | AB20: P | AC20: P | AG20: P | AH20: P | AI20: P | AS20: 45915 | AT20: 46037 | BH20: 45974 | BK20: 45964 | BQ20: =_xlfn.TEXTBEFORE($B20,".",2) -> 2.5 | BR20: =IF(OR(H20<>"",N20<>"",T20<>"",Z20<>"",AF20<>"",AL20<>"",AR20<>"",AU20<>""),TRUE,FALSE) -> FALSE
A21: =IF(OR(D21<>"",V21<>"",J21<>"",P21<>"",AB21<>"",AH21<>"",AN21<>"",AT21<>""),TRUE,FALSE) -> TRUE | B21: 3A.1.1 | I21: P | J21: P | K21: P | O21: P | P21: P | Q21: P | AS21: 45910 | AT21: 45982 | AY21: 45944 | BB21: 45923 | BQ21: =_xlfn.TEXTBEFORE($B21,".",2) -> 3A.1 | BR21: =IF(OR(H21<>"",N21<>"",T21<>"",Z21<>"",AF21<>"",AL21<>"",AR21<>"",AU21<>""),TRUE,FALSE) -> FALSE
A22: =IF(OR(D22<>"",V22<>"",J22<>"",P22<>"",AB22<>"",AH22<>"",AN22<>"",AT22<>""),TRUE,FALSE) -> TRUE | B22: 3A.2.1 | I22: P | J22: P | K22: P | O22: P | P22: P | Q22: P | AS22: 45911 | AT22: 46055 | AY22: 45986 | BB22: 45944 | BQ22: =_xlfn.TEXTBEFORE($B22,".",2) -> 3A.2 | BR22: =IF(OR(H22<>"",N22<>"",T22<>"",Z22<>"",AF22<>"",AL22<>"",AR22<>"",AU22<>""),TRUE,FALSE) -> FALSE
A23: =IF(OR(D23<>"",V23<>"",J23<>"",P23<>"",AB23<>"",AH23<>"",AN23<>"",AT23<>""),TRUE,FALSE) -> TRUE | B23: 4A.1.1 | AA23: P | AB23: P | AC23: P | AF23: P | AG23: P | AH23: P | AI23: P | AL23: P | AS23: 45888 | AT23: 45972 | AU23: 46252 | BH23: 45924 | BK23: 45960 | BQ23: =_xlfn.TEXTBEFORE($B23,".",2) -> 4A.1 | BR23: =IF(OR(H23<>"",N23<>"",T23<>"",Z23<>"",AF23<>"",AL23<>"",AR23<>"",AU23<>""),TRUE,FALSE) -> TRUE
A24: =IF(OR(D24<>"",V24<>"",J24<>"",P24<>"",AB24<>"",AH24<>"",AN24<>"",AT24<>""),TRUE,FALSE) -> TRUE | B24: 4A.1.2 | AA24: P | AB24: P | AC24: P | AG24: P | AH24: P | AI24: P | AS24: 45889 | AT24: 46072 | BH24: 45951 | BK24: 45965 | BQ24: =_xlfn.TEXTBEFORE($B24,".",2) -> 4A.1 | BR24: =IF(OR(H24<>"",N24<>"",T24<>"",Z24<>"",AF24<>"",AL24<>"",AR24<>"",AU24<>""),TRUE,FALSE) -> FALSE
A25: =IF(OR(D25<>"",V25<>"",J25<>"",P25<>"",AB25<>"",AH25<>"",AN25<>"",AT25<>""),TRUE,FALSE) -> TRUE | B25: 4A.1.3 | AA25: P | AB25: P | AC25: P | AG25: P | AH25: P | AI25: P | AS25: 45889 | AT25: 46062 | BH25: 45951 | BK25: 45965 | BQ25: =_xlfn.TEXTBEFORE($B25,".",2) -> 4A.1 | BR25: =IF(OR(H25<>"",N25<>"",T25<>"",Z25<>"",AF25<>"",AL25<>"",AR25<>"",AU25<>""),TRUE,FALSE) -> FALSE
A26: =IF(OR(D26<>"",V26<>"",J26<>"",P26<>"",AB26<>"",AH26<>"",AN26<>"",AT26<>""),TRUE,FALSE) -> TRUE | B26: 4A.1.4 | AA26: P | AB26: P | AC26: F | AD26: P | AG26: P | AH26: P | AI26: F | AJ26: P | AS26: 45890 | AT26: 46058 | BH26: 45953 | BI26: 46055 | BK26: 45967 | BL26: 46044 | BQ26: =_xlfn.TEXTBEFORE($B26,".",2) -> 4A.1 | BR26: =IF(OR(H26<>"",N26<>"",T26<>"",Z26<>"",AF26<>"",AL26<>"",AR26<>"",AU26<>""),TRUE,FALSE) -> FALSE
A27: =IF(OR(D27<>"",V27<>"",J27<>"",P27<>"",AB27<>"",AH27<>"",AN27<>"",AT27<>""),TRUE,FALSE) -> TRUE | B27: 4A.1.5 | AA27: P | AB27: P | AC27: P | AG27: P | AH27: P | AI27: P | AS27: 45890 | AT27: 46058 | BH27: 45957 | BK27: 45967 | BQ27: =_xlfn.TEXTBEFORE($B27,".",2) -> 4A.1 | BR27: =IF(OR(H27<>"",N27<>"",T27<>"",Z27<>"",AF27<>"",AL27<>"",AR27<>"",AU27<>""),TRUE,FALSE) -> FALSE
A28: =IF(OR(D28<>"",V28<>"",J28<>"",P28<>"",AB28<>"",AH28<>"",AN28<>"",AT28<>""),TRUE,FALSE) -> TRUE | B28: 4A.1.6 | AA28: P | AB28: P | AC28: P | AG28: P | AH28: P | AI28: P | AS28: 45894 | AT28: 46062 | BH28: 45957 | BK28: 45971 | BQ28: =_xlfn.TEXTBEFORE($B28,".",2) -> 4A.1 | BR28: =IF(OR(H28<>"",N28<>"",T28<>"",Z28<>"",AF28<>"",AL28<>"",AR28<>"",AU28<>""),TRUE,FALSE) -> FALSE
A29: =IF(OR(D29<>"",V29<>"",J29<>"",P29<>"",AB29<>"",AH29<>"",AN29<>"",AT29<>""),TRUE,FALSE) -> TRUE | B29: 4A.2.1 | AA29: P | AB29: R | AC29: P | AG29: P | AH29: R | AI29: P | AS29: 45894 | AT29: 46048 | BH29: 45958 | BK29: 45971 | BQ29: =_xlfn.TEXTBEFORE($B29,".",2) -> 4A.2 | BR29: =IF(OR(H29<>"",N29<>"",T29<>"",Z29<>"",AF29<>"",AL29<>"",AR29<>"",AU29<>""),TRUE,FALSE) -> FALSE
A30: =IF(OR(D30<>"",V30<>"",J30<>"",P30<>"",AB30<>"",AH30<>"",AN30<>"",AT30<>""),TRUE,FALSE) -> TRUE | B30: 4A.2.2 | AA30: P | AB30: P | AC30: P | AG30: P | AH30: P | AI30: P | AS30: 45895 | AT30: 46048 | BH30: 45958 | BK30: 45971 | BQ30: =_xlfn.TEXTBEFORE($B30,".",2) -> 4A.2 | BR30: =IF(OR(H30<>"",N30<>"",T30<>"",Z30<>"",AF30<>"",AL30<>"",AR30<>"",AU30<>""),TRUE,FALSE) -> FALSE
A31: =IF(OR(D31<>"",V31<>"",J31<>"",P31<>"",AB31<>"",AH31<>"",AN31<>"",AT31<>""),TRUE,FALSE) -> TRUE | B31: 4A.2.3 | AA31: P | AB31: P | AC31: P | AG31: P | AH31: P | AI31: P | AS31: 45895 | AT31: 46072 | BH31: 45959 | BK31: 45972 | BQ31: =_xlfn.TEXTBEFORE($B31,".",2) -> 4A.2 | BR31: =IF(OR(H31<>"",N31<>"",T31<>"",Z31<>"",AF31<>"",AL31<>"",AR31<>"",AU31<>""),TRUE,FALSE) -> FALSE
A32: =IF(OR(D32<>"",V32<>"",J32<>"",P32<>"",AB32<>"",AH32<>"",AN32<>"",AT32<>""),TRUE,FALSE) -> TRUE | B32: 4A.3.1 | AA32: P | AB32: P | AC32: P | AG32: P | AH32: P | AI32: P | AS32: 45896 | AT32: 46041 | BH32: 45959 | BK32: 45973 | BQ32: =_xlfn.TEXTBEFORE($B32,".",2) -> 4A.3 | BR32: =IF(OR(H32<>"",N32<>"",T32<>"",Z32<>"",AF32<>"",AL32<>"",AR32<>"",AU32<>""),TRUE,FALSE) -> FALSE
A33: =IF(OR(D33<>"",V33<>"",J33<>"",P33<>"",AB33<>"",AH33<>"",AN33<>"",AT33<>""),TRUE,FALSE) -> TRUE | B33: 4A.3.2 | AA33: P | AB33: P | AC33: P | AG33: P | AH33: P | AI33: P | AS33: 45896 | AT33: 46041 | BH33: 45960 | BK33: 45973 | BQ33: =_xlfn.TEXTBEFORE($B33,".",2) -> 4A.3 | BR33: =IF(OR(H33<>"",N33<>"",T33<>"",Z33<>"",AF33<>"",AL33<>"",AR33<>"",AU33<>""),TRUE,FALSE) -> FALSE
A34: =IF(OR(D34<>"",V34<>"",J34<>"",P34<>"",AB34<>"",AH34<>"",AN34<>"",AT34<>""),TRUE,FALSE) -> TRUE | B34: 4A.3.3 | AA34: P | AB34: P | AC34: P | AG34: P | AH34: P | AI34: P | AS34: 45897 | AT34: 46069 | BH34: 45960 | BK34: 45974 | BQ34: =_xlfn.TEXTBEFORE($B34,".",2) -> 4A.3 | BR34: =IF(OR(H34<>"",N34<>"",T34<>"",Z34<>"",AF34<>"",AL34<>"",AR34<>"",AU34<>""),TRUE,FALSE) -> FALSE
A35: =IF(OR(D35<>"",V35<>"",J35<>"",P35<>"",AB35<>"",AH35<>"",AN35<>"",AT35<>""),TRUE,FALSE) -> TRUE | B35: 5A.1.1 | I35: P | J35: P | K35: F | L35: P | U35: P | V35: P | W35: F | X35: P | AS35: 45901 | AT35: 46043 | AY35: 45937 | AZ35: 46050 | BE35: 45959 | BF35: 46050 | BQ35: =_xlfn.TEXTBEFORE($B35,".",2) -> 5A.1 | BR35: =IF(OR(H35<>"",N35<>"",T35<>"",Z35<>"",AF35<>"",AL35<>"",AR35<>"",AU35<>""),TRUE,FALSE) -> FALSE
A36: =IF(OR(D36<>"",V36<>"",J36<>"",P36<>"",AB36<>"",AH36<>"",AN36<>"",AT36<>""),TRUE,FALSE) -> TRUE | B36: 5A.1.2 | I36: P | J36: P | K36: P | U36: P | V36: P | W36: P | AS36: 45902 | AT36: 46044 | AY36: 45946 | BE36: 45960 | BQ36: =_xlfn.TEXTBEFORE($B36,".",2) -> 5A.1 | BR36: =IF(OR(H36<>"",N36<>"",T36<>"",Z36<>"",AF36<>"",AL36<>"",AR36<>"",AU36<>""),TRUE,FALSE) -> FALSE
A37: =IF(OR(D37<>"",V37<>"",J37<>"",P37<>"",AB37<>"",AH37<>"",AN37<>"",AT37<>""),TRUE,FALSE) -> TRUE | B37: 5A.2.1 | I37: P | J37: P | K37: P | U37: P | V37: P | W37: P | AS37: 45904 | AT37: 46050 | AY37: 45925 | BE37: 45964 | BQ37: =_xlfn.TEXTBEFORE($B37,".",2) -> 5A.2 | BR37: =IF(OR(H37<>"",N37<>"",T37<>"",Z37<>"",AF37<>"",AL37<>"",AR37<>"",AU37<>""),TRUE,FALSE) -> FALSE
A38: =IF(OR(D38<>"",V38<>"",J38<>"",P38<>"",AB38<>"",AH38<>"",AN38<>"",AT38<>""),TRUE,FALSE) -> TRUE | B38: 5A.2.2 | I38: P | J38: P | K38: P | U38: P | V38: P | W38: P | AS38: 45908 | AT38: 46051 | AY38: 45966 | BE38: 45966 | BQ38: =_xlfn.TEXTBEFORE($B38,".",2) -> 5A.2 | BR38: =IF(OR(H38<>"",N38<>"",T38<>"",Z38<>"",AF38<>"",AL38<>"",AR38<>"",AU38<>""),TRUE,FALSE) -> FALSE
A39: =IF(OR(D39<>"",V39<>"",J39<>"",P39<>"",AB39<>"",AH39<>"",AN39<>"",AT39<>""),TRUE,FALSE) -> TRUE | B39: 6A.1.1 | O39: P | P39: P | Q39: P | U39: P | V39: P | W39: P | Z39: O | AM39: R | AN39: P | AO39: F | AP39: P | AS39: 45895 | AT39: 46036 | BB39: 45937 | BE39: 45967 | BN39: 46041 | BO39: 46083 | BQ39: =_xlfn.TEXTBEFORE($B39,".",2) -> 6A.1 | BR39: =IF(OR(H39<>"",N39<>"",T39<>"",Z39<>"",AF39<>"",AL39<>"",AR39<>"",AU39<>""),TRUE,FALSE) -> TRUE
A40: =IF(OR(D40<>"",V40<>"",J40<>"",P40<>"",AB40<>"",AH40<>"",AN40<>"",AT40<>""),TRUE,FALSE) -> TRUE | B40: 6A.1.2 | O40: P | P40: P | Q40: P | U40: P | V40: P | W40: P | Z40: O | AM40: R | AN40: P | AO40: P | AS40: 45896 | AT40: 46056 | BB40: 45971 | BE40: 45968 | BN40: 46078 | BQ40: =_xlfn.TEXTBEFORE($B40,".",2) -> 6A.1 | BR40: =IF(OR(H40<>"",N40<>"",T40<>"",Z40<>"",AF40<>"",AL40<>"",AR40<>"",AU40<>""),TRUE,FALSE) -> TRUE
...

Sheet PW_CMI GRADE 10
C1: A | D1: ABSENT | P1: F | Q1: FAILED (STEPS C/D ONLY)
C2: P | D2: PRESENT | P2: R | Q2: REMEDIAL
C3: O | D3: OPTIONAL | P3: Cours Planifié
C4: X | D4: PARTIAL PRESENCE | P4: A CORRIGER
C5: DIKI | I5: RIZKI | O5: GITA | U5: GHATA | AA5: RAHMAT | AG5: AYUTYASTUTI | AM5: KARTIKA | AS5: DATE DE DIFFUSION | AV5: DIKI | AY5: RIZKI | BB5: GITA | BE5: GHATA | BH5: RAHMAT | BK5: AYUTYASTUTI | BN5: KARTIKA
A6: Batch#1 | C6: A | D6: B | E6: C1 | F6: C2 | G6: C3 | H6: D | I6: A | J6: B | K6: C1 | L6: C2 | M6: C3 | N6: D | O6: A | P6: B | Q6: C1 | R6: C2 | S6: C3 | T6: D | U6: A | V6: B | W6: C1 | X6: C2 | Y6: C3 | Z6: D | AA6: A | AB6: B | AC6: C1 | AD6: C2 | AE6: C3 | AF6: D | AG6: A | AH6: B | AI6: C1 | AJ6: C2 | AK6: C3 | AL6: D | AM6: A | AN6: B | AO6: C1 | AP6: C2 | AQ6: C3 | AR6: D | AS6: A | AT6: B | AU6: D | AV6: C1 | AW6: C2 | AX6: C3 | AY6: C1 | AZ6: C2 | BA6: C3 | BB6: C1 | BC6: C2 | BD6: C3 | BE6: C1 | BF6: C2 | BG6: C3 | BH6: C1 | BI6: C2 | BJ6: C3 | BK6: C1 | BL6: C2 | BM6: C3 | BN6: C1 | BO6: C2 | BP6: C3 | BR6: Batch#2
A7: =IF(OR(D7<>"",V7<>"",J7<>"",P7<>"",AB7<>"",AH7<>"",AN7<>"",AT7<>""),TRUE,FALSE) -> FALSE | B7: 2.1.1 | BQ7: =_xlfn.TEXTBEFORE($B7,".",2) -> 2.1 | BR7: =IF(OR(H7<>"",N7<>"",T7<>"",Z7<>"",AF7<>"",AL7<>"",AR7<>"",AU7<>""),TRUE,FALSE) -> FALSE
A8: =IF(OR(D8<>"",V8<>"",J8<>"",P8<>"",AB8<>"",AH8<>"",AN8<>"",AT8<>""),TRUE,FALSE) -> FALSE | B8: 2.1.2 | BQ8: =_xlfn.TEXTBEFORE($B8,".",2) -> 2.1 | BR8: =IF(OR(H8<>"",N8<>"",T8<>"",Z8<>"",AF8<>"",AL8<>"",AR8<>"",AU8<>""),TRUE,FALSE) -> FALSE
A9: =IF(OR(D9<>"",V9<>"",J9<>"",P9<>"",AB9<>"",AH9<>"",AN9<>"",AT9<>""),TRUE,FALSE) -> TRUE | B9: 2.1.4 | AA9: P | AB9: P | AC9: P | AG9: P | AH9: P | AI9: P | AS9: 46119 | AT9: 46128 | BH9: 46132 | BK9: 46132 | BQ9: =_xlfn.TEXTBEFORE($B9,".",2) -> 2.1 | BR9: =IF(OR(H9<>"",N9<>"",T9<>"",Z9<>"",AF9<>"",AL9<>"",AR9<>"",AU9<>""),TRUE,FALSE) -> FALSE
A10: =IF(OR(D10<>"",V10<>"",J10<>"",P10<>"",AB10<>"",AH10<>"",AN10<>"",AT10<>""),TRUE,FALSE) -> TRUE | B10: 2.1.5 | AA10: P | AB10: P | AC10: P | AG10: P | AH10: P | AI10: P | AS10: 46119 | AT10: 46128 | BH10: 46132 | BK10: 46132 | BQ10: =_xlfn.TEXTBEFORE($B10,".",2) -> 2.1 | BR10: =IF(OR(H10<>"",N10<>"",T10<>"",Z10<>"",AF10<>"",AL10<>"",AR10<>"",AU10<>""),TRUE,FALSE) -> FALSE
A11: =IF(OR(D11<>"",V11<>"",J11<>"",P11<>"",AB11<>"",AH11<>"",AN11<>"",AT11<>""),TRUE,FALSE) -> FALSE | B11: 2.1.6 | BQ11: =_xlfn.TEXTBEFORE($B11,".",2) -> 2.1 | BR11: =IF(OR(H11<>"",N11<>"",T11<>"",Z11<>"",AF11<>"",AL11<>"",AR11<>"",AU11<>""),TRUE,FALSE) -> FALSE
A12: =IF(OR(D12<>"",V12<>"",J12<>"",P12<>"",AB12<>"",AH12<>"",AN12<>"",AT12<>""),TRUE,FALSE) -> FALSE | B12: 2.3.2 | BQ12: =_xlfn.TEXTBEFORE($B12,".",2) -> 2.3 | BR12: =IF(OR(H12<>"",N12<>"",T12<>"",Z12<>"",AF12<>"",AL12<>"",AR12<>"",AU12<>""),TRUE,FALSE) -> FALSE
A13: =IF(OR(D13<>"",V13<>"",J13<>"",P13<>"",AB13<>"",AH13<>"",AN13<>"",AT13<>""),TRUE,FALSE) -> FALSE | B13: 2.3.3 | BQ13: =_xlfn.TEXTBEFORE($B13,".",2) -> 2.3 | BR13: =IF(OR(H13<>"",N13<>"",T13<>"",Z13<>"",AF13<>"",AL13<>"",AR13<>"",AU13<>""),TRUE,FALSE) -> FALSE
A14: =IF(OR(D14<>"",V14<>"",J14<>"",P14<>"",AB14<>"",AH14<>"",AN14<>"",AT14<>""),TRUE,FALSE) -> FALSE | B14: 2.3.4 | BQ14: =_xlfn.TEXTBEFORE($B14,".",2) -> 2.3 | BR14: =IF(OR(H14<>"",N14<>"",T14<>"",Z14<>"",AF14<>"",AL14<>"",AR14<>"",AU14<>""),TRUE,FALSE) -> FALSE
A15: =IF(OR(D15<>"",V15<>"",J15<>"",P15<>"",AB15<>"",AH15<>"",AN15<>"",AT15<>""),TRUE,FALSE) -> FALSE | B15: 2.5.1 | BQ15: =_xlfn.TEXTBEFORE($B15,".",2) -> 2.5 | BR15: =IF(OR(H15<>"",N15<>"",T15<>"",Z15<>"",AF15<>"",AL15<>"",AR15<>"",AU15<>""),TRUE,FALSE) -> FALSE
A16: =IF(OR(D16<>"",V16<>"",J16<>"",P16<>"",AB16<>"",AH16<>"",AN16<>"",AT16<>""),TRUE,FALSE) -> TRUE | B16: 3A.3.1 | I16: P | J16: P | K16: P | O16: P | P16: P | Q16: P | AS16: 46035 | AT16: 46085 | AY16: 46140 | BB16: 46146 | BQ16: =_xlfn.TEXTBEFORE($B16,".",2) -> 3A.3 | BR16: =IF(OR(H16<>"",N16<>"",T16<>"",Z16<>"",AF16<>"",AL16<>"",AR16<>"",AU16<>""),TRUE,FALSE) -> FALSE
A17: =IF(OR(D17<>"",V17<>"",J17<>"",P17<>"",AB17<>"",AH17<>"",AN17<>"",AT17<>""),TRUE,FALSE) -> TRUE | B17: 3A.3.2 | I17: P | J17: P | K17: P | O17: P | P17: P | Q17: P | AS17: 46041 | AT17: 46119 | AY17: 46140 | BB17: 46146 | BQ17: =_xlfn.TEXTBEFORE($B17,".",2) -> 3A.3 | BR17: =IF(OR(H17<>"",N17<>"",T17<>"",Z17<>"",AF17<>"",AL17<>"",AR17<>"",AU17<>""),TRUE,FALSE) -> FALSE
A18: =IF(OR(D18<>"",V18<>"",J18<>"",P18<>"",AB18<>"",AH18<>"",AN18<>"",AT18<>""),TRUE,FALSE) -> FALSE | B18: 4A.1.2 | BQ18: =_xlfn.TEXTBEFORE($B18,".",2) -> 4A.1 | BR18: =IF(OR(H18<>"",N18<>"",T18<>"",Z18<>"",AF18<>"",AL18<>"",AR18<>"",AU18<>""),TRUE,FALSE) -> FALSE
A19: =IF(OR(D19<>"",V19<>"",J19<>"",P19<>"",AB19<>"",AH19<>"",AN19<>"",AT19<>""),TRUE,FALSE) -> FALSE | B19: 4A.1.3 | BQ19: =_xlfn.TEXTBEFORE($B19,".",2) -> 4A.1 | BR19: =IF(OR(H19<>"",N19<>"",T19<>"",Z19<>"",AF19<>"",AL19<>"",AR19<>"",AU19<>""),TRUE,FALSE) -> FALSE
A20: =IF(OR(D20<>"",V20<>"",J20<>"",P20<>"",AB20<>"",AH20<>"",AN20<>"",AT20<>""),TRUE,FALSE) -> FALSE | B20: 4A.1.6 | U20: P | W20: F | X20: P | AA20: P | AC20: P | AG20: P | AI20: P | AS20: 46034 | BE20: 46134 | BF20: 46177 | BH20: 46175 | BK20: 46175 | BQ20: =_xlfn.TEXTBEFORE($B20,".",2) -> 4A.1 | BR20: =IF(OR(H20<>"",N20<>"",T20<>"",Z20<>"",AF20<>"",AL20<>"",AR20<>"",AU20<>""),TRUE,FALSE) -> FALSE
A21: =IF(OR(D21<>"",V21<>"",J21<>"",P21<>"",AB21<>"",AH21<>"",AN21<>"",AT21<>""),TRUE,FALSE) -> FALSE | B21: 4A.2.2 | AA21: P | AC21: P | AG21: P | AI21: P | AS21: 46120 | BH21: 46149 | BK21: 46141 | BQ21: =_xlfn.TEXTBEFORE($B21,".",2) -> 4A.2 | BR21: =IF(OR(H21<>"",N21<>"",T21<>"",Z21<>"",AF21<>"",AL21<>"",AR21<>"",AU21<>""),TRUE,FALSE) -> FALSE
A22: =IF(OR(D22<>"",V22<>"",J22<>"",P22<>"",AB22<>"",AH22<>"",AN22<>"",AT22<>""),TRUE,FALSE) -> FALSE | B22: 4A.2.3 | BQ22: =_xlfn.TEXTBEFORE($B22,".",2) -> 4A.2 | BR22: =IF(OR(H22<>"",N22<>"",T22<>"",Z22<>"",AF22<>"",AL22<>"",AR22<>"",AU22<>""),TRUE,FALSE) -> FALSE
A23: =IF(OR(D23<>"",V23<>"",J23<>"",P23<>"",AB23<>"",AH23<>"",AN23<>"",AT23<>""),TRUE,FALSE) -> FALSE | B23: 4A.3.1 | BQ23: =_xlfn.TEXTBEFORE($B23,".",2) -> 4A.3 | BR23: =IF(OR(H23<>"",N23<>"",T23<>"",Z23<>"",AF23<>"",AL23<>"",AR23<>"",AU23<>""),TRUE,FALSE) -> FALSE
A24: =IF(OR(D24<>"",V24<>"",J24<>"",P24<>"",AB24<>"",AH24<>"",AN24<>"",AT24<>""),TRUE,FALSE) -> FALSE | B24: 4A.3.3 | BQ24: =_xlfn.TEXTBEFORE($B24,".",2) -> 4A.3 | BR24: =IF(OR(H24<>"",N24<>"",T24<>"",Z24<>"",AF24<>"",AL24<>"",AR24<>"",AU24<>""),TRUE,FALSE) -> FALSE
A25: =IF(OR(D25<>"",V25<>"",J25<>"",P25<>"",AB25<>"",AH25<>"",AN25<>"",AT25<>""),TRUE,FALSE) -> FALSE | B25: 5A.1.1 | I25: P | K25: P | U25: P | W25: P | AS25: 46041 | AY25: 46176 | BE25: 46182 | BQ25: =_xlfn.TEXTBEFORE($B25,".",2) -> 5A.1 | BR25: =IF(OR(H25<>"",N25<>"",T25<>"",Z25<>"",AF25<>"",AL25<>"",AR25<>"",AU25<>""),TRUE,FALSE) -> FALSE
A26: =IF(OR(D26<>"",V26<>"",J26<>"",P26<>"",AB26<>"",AH26<>"",AN26<>"",AT26<>""),TRUE,FALSE) -> FALSE | B26: 5A.2.1 | I26: P | U26: P | W26: P | AS26: 46043 | BE26: 46183 | BQ26: =_xlfn.TEXTBEFORE($B26,".",2) -> 5A.2 | BR26: =IF(OR(H26<>"",N26<>"",T26<>"",Z26<>"",AF26<>"",AL26<>"",AR26<>"",AU26<>""),TRUE,FALSE) -> FALSE
A27: =IF(OR(D27<>"",V27<>"",J27<>"",P27<>"",AB27<>"",AH27<>"",AN27<>"",AT27<>""),TRUE,FALSE) -> FALSE | B27: 5A.2.2 | BQ27: =_xlfn.TEXTBEFORE($B27,".",2) -> 5A.2 | BR27: =IF(OR(H27<>"",N27<>"",T27<>"",Z27<>"",AF27<>"",AL27<>"",AR27<>"",AU27<>""),TRUE,FALSE) -> FALSE
A28: =IF(OR(D28<>"",V28<>"",J28<>"",P28<>"",AB28<>"",AH28<>"",AN28<>"",AT28<>""),TRUE,FALSE) -> TRUE | B28: 6A.1.1 | O28: P | P28: P | Q28: P | AM28: P | AN28: P | AO28: P | AS28: 46135 | AT28: 46132 | BB28: 46142 | BN28: 46167 | BQ28: =_xlfn.TEXTBEFORE($B28,".",2) -> 6A.1 | BR28: =IF(OR(H28<>"",N28<>"",T28<>"",Z28<>"",AF28<>"",AL28<>"",AR28<>"",AU28<>""),TRUE,FALSE) -> FALSE
A29: =IF(OR(D29<>"",V29<>"",J29<>"",P29<>"",AB29<>"",AH29<>"",AN29<>"",AT29<>""),TRUE,FALSE) -> FALSE | B29: 6A.1.2 | BQ29: =_xlfn.TEXTBEFORE($B29,".",2) -> 6A.1 | BR29: =IF(OR(H29<>"",N29<>"",T29<>"",Z29<>"",AF29<>"",AL29<>"",AR29<>"",AU29<>""),TRUE,FALSE) -> FALSE
A30: =IF(OR(D30<>"",V30<>"",J30<>"",P30<>"",AB30<>"",AH30<>"",AN30<>"",AT30<>""),TRUE,FALSE) -> FALSE | B30: 6A.2.2 | O30: O | U30: P | AM30: P | AS30: 46050 | BQ30: =_xlfn.TEXTBEFORE($B30,".",2) -> 6A.2 | BR30: =IF(OR(H30<>"",N30<>"",T30<>"",Z30<>"",AF30<>"",AL30<>"",AR30<>"",AU30<>""),TRUE,FALSE) -> FALSE
A31: =IF(OR(D31<>"",V31<>"",J31<>"",P31<>"",AB31<>"",AH31<>"",AN31<>"",AT31<>""),TRUE,FALSE) -> FALSE | B31: 6A.2.3 | BQ31: =_xlfn.TEXTBEFORE($B31,".",2) -> 6A.2 | BR31: =IF(OR(H31<>"",N31<>"",T31<>"",Z31<>"",AF31<>"",AL31<>"",AR31<>"",AU31<>""),TRUE,FALSE) -> FALSE
A32: =COUNTIF(A7:A31,TRUE)/COUNTA(B7:B31) -> 0.2 | BR32: =COUNTIF(BR7:BR31,TRUE)/COUNTA(B7:B31) -> 0

Sheet TH_CMI GRADE 11
C1: A | D1: ABSENT | P1: F | Q1: FAILED (STEPS C/D ONLY) | AR1: FALSE
C2: P | D2: PRESENT | P2: R | Q2: REMEDIAL
C3: O | D3: OPTIONAL | P3: Cours Planifié
C4: X | D4: PARTIAL PRESENCE | P4: A CORRIGER
C5: DIKI | I5: RIZKI | O5: GITA | U5: GHATA | AA5: RAHMAT | AG5: AYUTYASTUTI | AM5: KARTIKA | AS5: DATE DE DIFFUSION | AV5: DIKI | AY5: RIZKY | BB5: GITA | BE5: GHATA | BH5: RAHMAT | BK5: AYUTYASTUTI | BN5: KARTIKA
A6: Batch#1 | C6: A | D6: B | E6: C1 | F6: C2 | G6: C3 | H6: D | I6: A | J6: B | K6: C1 | L6: C2 | M6: C3 | N6: D | O6: A | P6: B | Q6: C1 | R6: C2 | S6: C3 | T6: D | U6: A | V6: B | W6: C1 | X6: C2 | Y6: C3 | Z6: D | AA6: A | AB6: B | AC6: C1 | AD6: C2 | AE6: C3 | AF6: D | AG6: A | AH6: B | AI6: C1 | AJ6: C2 | AK6: C3 | AL6: D | AM6: A | AN6: B | AO6: C1 | AP6: C2 | AQ6: C3 | AR6: D | AS6: A | AT6: B | AU6: D | AV6: C1 | AW6: C2 | AX6: C3 | AY6: C1 | AZ6: C2 | BA6: C3 | BB6: C1 | BC6: C2 | BD6: C3 | BE6: C1 | BF6: C2 | BG6: C3 | BH6: C1 | BI6: C2 | BJ6: C3 | BK6: C1 | BL6: C2 | BM6: C3 | BN6: C1 | BO6: C2 | BP6: C3 | BR6: Batch#2
A7: =IF(OR(D7<>"",V7<>"",J7<>"",P7<>"",AB7<>"",AH7<>"",AN7<>"",AT7<>""),TRUE,FALSE) -> TRUE | B7: 9.1.1 | AA7: P | AB7: P | AC7: P | AG7: P | AH7: P | AI7: P | AS7: 46078 | AT7: 46219 | BH7: 46161 | BK7: 46162 | BQ7: =_xlfn.TEXTBEFORE($B7,".",2) -> 9.1 | BR7: =IF(OR(H7<>"",N7<>"",T7<>"",Z7<>"",AF7<>"",AL7<>"",AR7<>"",AU7<>""),TRUE,FALSE) -> FALSE
A8: =IF(OR(D8<>"",V8<>"",J8<>"",P8<>"",AB8<>"",AH8<>"",AN8<>"",AT8<>""),TRUE,FALSE) -> TRUE | B8: 9.1.2 | AA8: P | AB8: P | AC8: P | AG8: P | AH8: P | AI8: P | AS8: 46078 | AT8: 46223 | BH8: 46163 | BK8: 46163 | BQ8: =_xlfn.TEXTBEFORE($B8,".",2) -> 9.1 | BR8: =IF(OR(H8<>"",N8<>"",T8<>"",Z8<>"",AF8<>"",AL8<>"",AR8<>"",AU8<>""),TRUE,FALSE) -> FALSE
A9: =IF(OR(D9<>"",V9<>"",J9<>"",P9<>"",AB9<>"",AH9<>"",AN9<>"",AT9<>""),TRUE,FALSE) -> TRUE | B9: 9.1.3 | AA9: P | AB9: P | AC9: P | AG9: P | AH9: P | AI9: P | AS9: 46078 | AT9: 46224 | BH9: 46182 | BK9: 46182 | BQ9: =_xlfn.TEXTBEFORE($B9,".",2) -> 9.1 | BR9: =IF(OR(H9<>"",N9<>"",T9<>"",Z9<>"",AF9<>"",AL9<>"",AR9<>"",AU9<>""),TRUE,FALSE) -> FALSE
A10: =IF(OR(D10<>"",V10<>"",J10<>"",P10<>"",AB10<>"",AH10<>"",AN10<>"",AT10<>""),TRUE,FALSE) -> TRUE | B10: 9.2.1 | AA10: P | AB10: P | AC10: P | AG10: P | AH10: P | AI10: P | AS10: 46079 | AT10: 46225 | BH10: 46183 | BK10: 46183 | BQ10: =_xlfn.TEXTBEFORE($B10,".",2) -> 9.2 | BR10: =IF(OR(H10<>"",N10<>"",T10<>"",Z10<>"",AF10<>"",AL10<>"",AR10<>"",AU10<>""),TRUE,FALSE) -> FALSE
A11: =IF(OR(D11<>"",V11<>"",J11<>"",P11<>"",AB11<>"",AH11<>"",AN11<>"",AT11<>""),TRUE,FALSE) -> TRUE | B11: 9.3.1 | AA11: P | AB11: P | AC11: P | AG11: P | AH11: P | AI11: P | AS11: 46086 | AT11: 46226 | BH11: 46184 | BK11: 46184 | BQ11: =_xlfn.TEXTBEFORE($B11,".",2) -> 9.3 | BR11: =IF(OR(H11<>"",N11<>"",T11<>"",Z11<>"",AF11<>"",AL11<>"",AR11<>"",AU11<>""),TRUE,FALSE) -> FALSE
A12: =IF(OR(D12<>"",V12<>"",J12<>"",P12<>"",AB12<>"",AH12<>"",AN12<>"",AT12<>""),TRUE,FALSE) -> TRUE | B12: 9.4.1 | AA12: P | AB12: P | AC12: P | AG12: P | AH12: P | AI12: P | AS12: 46162 | AT12: 46219 | BH12: 46162 | BK12: 46162 | BQ12: =_xlfn.TEXTBEFORE($B12,".",2) -> 9.4 | BR12: =IF(OR(H12<>"",N12<>"",T12<>"",Z12<>"",AF12<>"",AL12<>"",AR12<>"",AU12<>""),TRUE,FALSE) -> FALSE
A13: =IF(OR(D13<>"",V13<>"",J13<>"",P13<>"",AB13<>"",AH13<>"",AN13<>"",AT13<>""),TRUE,FALSE) -> TRUE | B13: 3B.1.1 | I13: P | J13: P | K13: P | O13: P | P13: P | Q13: P | AS13: 46077 | AT13: 46153 | AY13: 46226 | BB13: 46231 | BQ13: =_xlfn.TEXTBEFORE($B13,".",2) -> 3B.1 | BR13: =IF(OR(H13<>"",N13<>"",T13<>"",Z13<>"",AF13<>"",AL13<>"",AR13<>"",AU13<>""),TRUE,FALSE) -> FALSE
A14: =IF(OR(D14<>"",V14<>"",J14<>"",P14<>"",AB14<>"",AH14<>"",AN14<>"",AT14<>""),TRUE,FALSE) -> TRUE | B14: 3B.1.2 | I14: P | J14: P | K14: P | O14: P | P14: P | Q14: P | AS14: 46077 | AT14: 46153 | AY14: 46226 | BB14: 46231 | BQ14: =_xlfn.TEXTBEFORE($B14,".",2) -> 3B.1 | BR14: =IF(OR(H14<>"",N14<>"",T14<>"",Z14<>"",AF14<>"",AL14<>"",AR14<>"",AU14<>""),TRUE,FALSE) -> FALSE
A15: =IF(OR(D15<>"",V15<>"",J15<>"",P15<>"",AB15<>"",AH15<>"",AN15<>"",AT15<>""),TRUE,FALSE) -> FALSE | B15: 3B.2.1 | I15: P | K15: P | O15: P | Q15: P | AS15: 46093 | AY15: 46240 | BB15: 46232 | BQ15: =_xlfn.TEXTBEFORE($B15,".",2) -> 3B.2 | BR15: =IF(OR(H15<>"",N15<>"",T15<>"",Z15<>"",AF15<>"",AL15<>"",AR15<>"",AU15<>""),TRUE,FALSE) -> FALSE
A16: =IF(OR(D16<>"",V16<>"",J16<>"",P16<>"",AB16<>"",AH16<>"",AN16<>"",AT16<>""),TRUE,FALSE) -> FALSE | B16: 3B.2.2 | I16: P | K16: P | O16: P | Q16: P | AS16: 46120 | AY16: 46232 | BB16: 46232 | BQ16: =_xlfn.TEXTBEFORE($B16,".",2) -> 3B.2 | BR16: =IF(OR(H16<>"",N16<>"",T16<>"",Z16<>"",AF16<>"",AL16<>"",AR16<>"",AU16<>""),TRUE,FALSE) -> FALSE
A17: =IF(OR(D17<>"",V17<>"",J17<>"",P17<>"",AB17<>"",AH17<>"",AN17<>"",AT17<>""),TRUE,FALSE) -> FALSE | B17: 3B.2.3 | I17: P | K17: P | O17: P | Q17: P | AS17: 46223 | AY17: 46233 | BB17: 46233 | BQ17: =_xlfn.TEXTBEFORE($B17,".",2) -> 3B.2 | BR17: =IF(OR(H17<>"",N17<>"",T17<>"",Z17<>"",AF17<>"",AL17<>"",AR17<>"",AU17<>""),TRUE,FALSE) -> FALSE
A18: =IF(OR(D18<>"",V18<>"",J18<>"",P18<>"",AB18<>"",AH18<>"",AN18<>"",AT18<>""),TRUE,FALSE) -> TRUE | B18: 3B.3.1 | I18: P | J18: P | K18: P | O18: P | P18: P | Q18: P | AS18: 46163 | AT18: 46163 | AY18: 46237 | BB18: 46237 | BQ18: =_xlfn.TEXTBEFORE($B18,".",2) -> 3B.3 | BR18: =IF(OR(H18<>"",N18<>"",T18<>"",Z18<>"",AF18<>"",AL18<>"",AR18<>"",AU18<>""),TRUE,FALSE) -> FALSE
A19: =IF(OR(D19<>"",V19<>"",J19<>"",P19<>"",AB19<>"",AH19<>"",AN19<>"",AT19<>""),TRUE,FALSE) -> FALSE | B19: 3B.3.2 | I19: P | K19: P | O19: P | Q19: P | AS19: 46223 | AY19: 46238 | BB19: 46238 | BQ19: =_xlfn.TEXTBEFORE($B19,".",2) -> 3B.3 | BR19: =IF(OR(H19<>"",N19<>"",T19<>"",Z19<>"",AF19<>"",AL19<>"",AR19<>"",AU19<>""),TRUE,FALSE) -> FALSE
A20: =IF(OR(D20<>"",V20<>"",J20<>"",P20<>"",AB20<>"",AH20<>"",AN20<>"",AT20<>""),TRUE,FALSE) -> TRUE | B20: 4B.1.1 | AA20: P | AB20: P | AC20: P | AG20: P | AH20: P | AI20: P | AS20: 46084 | AT20: 46134 | BH20: 46153 | BK20: 46149 | BQ20: =_xlfn.TEXTBEFORE($B20,".",2) -> 4B.1 | BR20: =IF(OR(H20<>"",N20<>"",T20<>"",Z20<>"",AF20<>"",AL20<>"",AR20<>"",AU20<>""),TRUE,FALSE) -> FALSE
A21: =IF(OR(D21<>"",V21<>"",J21<>"",P21<>"",AB21<>"",AH21<>"",AN21<>"",AT21<>""),TRUE,FALSE) -> TRUE | B21: 4B.1.2 | AA21: P | AB21: P | AC21: P | AG21: P | AH21: P | AI21: P | AS21: 46083 | AT21: 46230 | BH21: 46231 | BK21: 46225 | BQ21: =_xlfn.TEXTBEFORE($B21,".",2) -> 4B.1 | BR21: =IF(OR(H21<>"",N21<>"",T21<>"",Z21<>"",AF21<>"",AL21<>"",AR21<>"",AU21<>""),TRUE,FALSE) -> FALSE
A22: =IF(OR(D22<>"",V22<>"",J22<>"",P22<>"",AB22<>"",AH22<>"",AN22<>"",AT22<>""),TRUE,FALSE) -> TRUE | B22: 4B.1.3 | AA22: P | AB22: P | AC22: P | AG22: P | AH22: P | AI22: P | AS22: 46083 | AT22: 46230 | BH22: 46238 | BK22: 46225 | BQ22: =_xlfn.TEXTBEFORE($B22,".",2) -> 4B.1 | BR22: =IF(OR(H22<>"",N22<>"",T22<>"",Z22<>"",AF22<>"",AL22<>"",AR22<>"",AU22<>""),TRUE,FALSE) -> FALSE
A23: =IF(OR(D23<>"",V23<>"",J23<>"",P23<>"",AB23<>"",AH23<>"",AN23<>"",AT23<>""),TRUE,FALSE) -> TRUE | B23: 4B.2.1 | U23: P | V23: P | W23: P | AM23: P | AN23: P | AO23: P | AS23: 46090 | AT23: 46231 | BE23: 46237 | BN23: 46237 | BQ23: =_xlfn.TEXTBEFORE($B23,".",2) -> 4B.2 | BR23: =IF(OR(H23<>"",N23<>"",T23<>"",Z23<>"",AF23<>"",AL23<>"",AR23<>"",AU23<>""),TRUE,FALSE) -> FALSE
A24: =IF(OR(D24<>"",V24<>"",J24<>"",P24<>"",AB24<>"",AH24<>"",AN24<>"",AT24<>""),TRUE,FALSE) -> TRUE | B24: 4B.2.2 | U24: P | V24: P | W24: P | AM24: P | AN24: P | AO24: P | AS24: 46090 | AT24: 46231 | BE24: 46237 | BN24: 46237 | BQ24: =_xlfn.TEXTBEFORE($B24,".",2) -> 4B.2 | BR24: =IF(OR(H24<>"",N24<>"",T24<>"",Z24<>"",AF24<>"",AL24<>"",AR24<>"",AU24<>""),TRUE,FALSE) -> FALSE
A25: =IF(OR(D25<>"",V25<>"",J25<>"",P25<>"",AB25<>"",AH25<>"",AN25<>"",AT25<>""),TRUE,FALSE) -> TRUE | B25: 4B.3.1 | I25: P | J25: P | K25: P | O25: P | P25: P | Q25: P | AS25: 46154 | AT25: 46232 | AY25: 46230 | BB25: 46225 | BQ25: =_xlfn.TEXTBEFORE($B25,".",2) -> 4B.3 | BR25: =IF(OR(H25<>"",N25<>"",T25<>"",Z25<>"",AF25<>"",AL25<>"",AR25<>"",AU25<>""),TRUE,FALSE) -> FALSE
A26: =IF(OR(D26<>"",V26<>"",J26<>"",P26<>"",AB26<>"",AH26<>"",AN26<>"",AT26<>""),TRUE,FALSE) -> TRUE | B26: 4B.3.2 | I26: P | J26: P | K26: P | O26: P | P26: P | Q26: P | AS26: 46141 | AT26: 46232 | AY26: 46141 | BB26: 46142 | BQ26: =_xlfn.TEXTBEFORE($B26,".",2) -> 4B.3 | BR26: =IF(OR(H26<>"",N26<>"",T26<>"",Z26<>"",AF26<>"",AL26<>"",AR26<>"",AU26<>""),TRUE,FALSE) -> FALSE
A27: =IF(OR(D27<>"",V27<>"",J27<>"",P27<>"",AB27<>"",AH27<>"",AN27<>"",AT27<>""),TRUE,FALSE) -> TRUE | B27: 4B.3.3 | I27: P | J27: P | K27: P | O27: P | P27: P | Q27: P | AS27: 46162 | AT27: 46233 | AY27: 46230 | BB27: 46227 | BQ27: =_xlfn.TEXTBEFORE($B27,".",2) -> 4B.3 | BR27: =IF(OR(H27<>"",N27<>"",T27<>"",Z27<>"",AF27<>"",AL27<>"",AR27<>"",AU27<>""),TRUE,FALSE) -> FALSE
A28: =IF(OR(D28<>"",V28<>"",J28<>"",P28<>"",AB28<>"",AH28<>"",AN28<>"",AT28<>""),TRUE,FALSE) -> TRUE | B28: 4B.3.4 | I28: P | J28: P | K28: P | O28: P | P28: P | AS28: 46163 | AT28: 46233 | AY28: 46245 | BQ28: =_xlfn.TEXTBEFORE($B28,".",2) -> 4B.3 | BR28: =IF(OR(H28<>"",N28<>"",T28<>"",Z28<>"",AF28<>"",AL28<>"",AR28<>"",AU28<>""),TRUE,FALSE) -> FALSE
A29: =IF(OR(D29<>"",V29<>"",J29<>"",P29<>"",AB29<>"",AH29<>"",AN29<>"",AT29<>""),TRUE,FALSE) -> TRUE | B29: 4B.3.5 | I29: P | J29: P | K29: P | O29: P | P29: P | AS29: 46226 | AT29: 46237 | AY29: 46245 | BQ29: =_xlfn.TEXTBEFORE($B29,".",2) -> 4B.3 | BR29: =IF(OR(H29<>"",N29<>"",T29<>"",Z29<>"",AF29<>"",AL29<>"",AR29<>"",AU29<>""),TRUE,FALSE) -> FALSE
